Workbook

Sheet Promotion
B1: Promotion Samsung | X1: https://nimbus.copperwired.co.th/ofs/query/InventoryControl.asp
E2: Stock ชั้น1 | F2: Stock ชั้น2 | G2: PROMOTION | H2: ราคาหลังหักส่วนลด PROMOTION | I2: คูปอง | J2: PROMOTION | K2: ราคาหลังหักส่วนลด PROMOTION | L2: คูปอง | M2: PROMOTION | N2: ราคาหลังหักส่วนลด PROMOTION | O2: คูปอง | P2: PROMOTION Student | Q2: ราคาหลังหักส่วนลด PROMOTION | S2: PROMOTION | T2: ราคาหลังหักส่วนลด PROMOTION | U2: คูปอง | V2: Remark | W2: หมายเหยุ
A3: *กรณีสินค้ามีราคาพิเศษ Flash Sales งดแถมของ Premium* | G3: 2Aug - 6 Sep 2026 | P3: Student
A4: Galaxy A07 4G 4/64 GB | B4: SM-A075FLVDTHL | C4: Light Violet | D4: 4599 | E4: {=_xlfn.XLOOKUP(B4,Stock1!F:F,Stock1!J:J,"")} -> 2 | F4: {=_xlfn.XLOOKUP(B4,Stock2!F:F,Stock2!J:J,"")} -> 5 | G4: 800 | H4: =D4-G4 -> 3799 | I4: 01 *ร่วม SF+
B5: SM-A075FZKDTHL | C5: Black | D5: 4599 | E5: {=_xlfn.XLOOKUP(B5,Stock1!F:F,Stock1!J:J,"")} | F5: {=_xlfn.XLOOKUP(B5,Stock2!F:F,Stock2!J:J,"")} | G5: 800 | H5: =D5-G5 -> 3799
B6: SM-A075FLVJTHL | C6: Light Violet | D6: 4599 | E6: {=_xlfn.XLOOKUP(B6,Stock1!F:F,Stock1!J:J,"")} | F6: {=_xlfn.XLOOKUP(B6,Stock2!F:F,Stock2!J:J,"")} | G6: 800 | H6: =D6-G6 -> 3799
B7: SM-A075FZKJTHL | C7: Black | D7: 4599 | E7: {=_xlfn.XLOOKUP(B7,Stock1!F:F,Stock1!J:J,"")} | F7: {=_xlfn.XLOOKUP(B7,Stock2!F:F,Stock2!J:J,"")} | G7: 800 | H7: =D7-G7 -> 3799
A8: Galaxy A07 4/64GB - BOM SET | B8: F-A074G064VDTH | C8: Light Violet | D8: 4599 | E8: {=_xlfn.XLOOKUP(B8,Stock1!F:F,Stock1!J:J,"")} | F8: {=_xlfn.XLOOKUP(B8,Stock2!F:F,Stock2!J:J,"")} | G8: 800 | H8: =D8-G8 -> 3799
B9: F-A074G064KDTH | C9: Black | D9: 4599 | E9: {=_xlfn.XLOOKUP(B9,Stock1!F:F,Stock1!J:J,"")} | F9: {=_xlfn.XLOOKUP(B9,Stock2!F:F,Stock2!J:J,"")} | G9: 800 | H9: =D9-G9 -> 3799
A10: Galaxy A07 4/128GB - BOM SET | B10: F-A074G128VGTH | C10: Light Violet | D10: 5299 | E10: {=_xlfn.XLOOKUP(B10,Stock1!F:F,Stock1!J:J,"")} | F10: {=_xlfn.XLOOKUP(B10,Stock2!F:F,Stock2!J:J,"")} | G10: 1000 | H10: =D10-G10 -> 4299
B11: F-A074G128KGTH | C11: Black | D11: 5299 | E11: {=_xlfn.XLOOKUP(B11,Stock1!F:F,Stock1!J:J,"")} | F11: {=_xlfn.XLOOKUP(B11,Stock2!F:F,Stock2!J:J,"")} | G11: 1000 | H11: =D11-G11 -> 4299
A12: Galaxy A07 4/128GB | B12: SM-A075FLVGTHL | C12: Light Violet | D12: 5299 | E12: {=_xlfn.XLOOKUP(B12,Stock1!F:F,Stock1!J:J,"")} | F12: {=_xlfn.XLOOKUP(B12,Stock2!F:F,Stock2!J:J,"")} -> 1 | G12: 1000 | H12: =D12-G12 -> 4299
B13: SM-A075FZKGTHL | C13: Black | D13: 5299 | E13: {=_xlfn.XLOOKUP(B13,Stock1!F:F,Stock1!J:J,"")} | F13: {=_xlfn.XLOOKUP(B13,Stock2!F:F,Stock2!J:J,"")} -> 12 | G13: 1000 | H13: =D13-G13 -> 4299
A14: Galaxy A07 6/128GB | B14: SM-A075FLVHTHL | C14: Light Violet | D14: 5999 | E14: {=_xlfn.XLOOKUP(B14,Stock1!F:F,Stock1!J:J,"")} -> 4 | F14: {=_xlfn.XLOOKUP(B14,Stock2!F:F,Stock2!J:J,"")} -> 3 | G14: 1000 | H14: =D14-G14 -> 4999
B15: SM-A075FZKHTHL | C15: Black | D15: 5999 | E15: {=_xlfn.XLOOKUP(B15,Stock1!F:F,Stock1!J:J,"")} -> 5 | F15: {=_xlfn.XLOOKUP(B15,Stock2!F:F,Stock2!J:J,"")} -> 2 | G15: 1000 | H15: =D15-G15 -> 4999
A16: Galaxy A07 5G 6/128GB | B16: SM-A076BLVCTHL | C16: Light Violet | D16: 6999 | E16: {=_xlfn.XLOOKUP(B16,Stock1!F:F,Stock1!J:J,"")} -> 6 | F16: {=_xlfn.XLOOKUP(B16,Stock2!F:F,Stock2!J:J,"")} -> 5 | I16: ดาวน์ไม่เกิน 13% | J16: 500 | K16: =D16-J16 -> 6499 | L16: 01 *ไม่ร่วม SF+ | P16: 0.1 | Q16: =ROUNDUP(D16-(D16*0.1),0) -> 6300
B17: SM-A076BZKCTHL | C17: Black | D17: 6999 | E17: {=_xlfn.XLOOKUP(B17,Stock1!F:F,Stock1!J:J,"")} -> 5 | F17: {=_xlfn.XLOOKUP(B17,Stock2!F:F,Stock2!J:J,"")} -> 7 | J17: 500 | K17: =D17-J17 -> 6499 | P17: 0.1 | Q17: =ROUNDUP(D17-(D17*0.1),0) -> 6300
A18: Galaxy A17 LTE 8/128 GB | B18: F-A174G128BDTH | C18: Light Blue | D18: 7999 | E18: {=_xlfn.XLOOKUP(B18,Stock1!F:F,Stock1!J:J,"")} | F18: {=_xlfn.XLOOKUP(B18,Stock2!F:F,Stock2!J:J,"")} | G18: 1000 | H18: =D18-G18 -> 6999 | I18: 01 *ร่วม SF+
B19: F-A174G128KDTH | C19: Black | D19: 7999 | E19: {=_xlfn.XLOOKUP(B19,Stock1!F:F,Stock1!J:J,"")} | F19: {=_xlfn.XLOOKUP(B19,Stock2!F:F,Stock2!J:J,"")} | G19: 1000 | H19: =D19-G19 -> 6999
B20: SM-A175FLBDTHL | C20: Light Blue | D20: 7999 | E20: {=_xlfn.XLOOKUP(B20,Stock1!F:F,Stock1!J:J,"")} | F20: {=_xlfn.XLOOKUP(B20,Stock2!F:F,Stock2!J:J,"")} -> 4 | G20: 1000 | H20: =D20-G20 -> 6999
B21: SM-A175FZKDTHL | C21: Black | D21: 7999 | E21: {=_xlfn.XLOOKUP(B21,Stock1!F:F,Stock1!J:J,"")} | F21: {=_xlfn.XLOOKUP(B21,Stock2!F:F,Stock2!J:J,"")} | G21: 1000 | H21: =D21-G21 -> 6999
A22: Galaxy A17 5G 8/128 GB | B22: SM-A176BZBJTHL | C22: Blue | D22: 8999 | E22: {=_xlfn.XLOOKUP(B22,Stock1!F:F,Stock1!J:J,"")} -> 3 | F22: {=_xlfn.XLOOKUP(B22,Stock2!F:F,Stock2!J:J,"")} -> 6 | G22: 1500 | H22: =D22-G22 -> 7499
B23: SM-A176BZKJTHL | C23: Black | D23: 8999 | E23: {=_xlfn.XLOOKUP(B23,Stock1!F:F,Stock1!J:J,"")} -> 7 | F23: {=_xlfn.XLOOKUP(B23,Stock2!F:F,Stock2!J:J,"")} -> 7 | G23: 1500 | H23: =D23-G23 -> 7499
B24: F-A175G128BLTH | C24: Blue | D24: 8999 | E24: {=_xlfn.XLOOKUP(B24,Stock1!F:F,Stock1!J:J,"")} | F24: {=_xlfn.XLOOKUP(B24,Stock2!F:F,Stock2!J:J,"")} | G24: 1500 | H24: =D24-G24 -> 7499
B25: F-A175G128BKTH | C25: Black | D25: 8999 | E25: {=_xlfn.XLOOKUP(B25,Stock1!F:F,Stock1!J:J,"")} | F25: {=_xlfn.XLOOKUP(B25,Stock2!F:F,Stock2!J:J,"")} | G25: 1500 | H25: =D25-G25 -> 7499
A26: Galaxy A17 5G 8/256 GB | B26: SM-A176BZBKTHL | C26: Blue | D26: 10599 | E26: {=_xlfn.XLOOKUP(B26,Stock1!F:F,Stock1!J:J,"")} -> 3 | F26: {=_xlfn.XLOOKUP(B26,Stock2!F:F,Stock2!J:J,"")} -> 5 | G26: 1600 | H26: =D26-G26 -> 8999 | P26: 0.1 | Q26: =ROUNDUP(D26-(D26*0.1),0) -> 9540
B27: SM-A176BZKKTHL | C27: Black | D27: 10599 | E27: {=_xlfn.XLOOKUP(B27,Stock1!F:F,Stock1!J:J,"")} -> 2 | F27: {=_xlfn.XLOOKUP(B27,Stock2!F:F,Stock2!J:J,"")} -> 4 | G27: 1600 | H27: =D27-G27 -> 8999 | P27: 0.1 | Q27: =ROUNDUP(D27-(D27*0.1),0) -> 9540
B28: F-A175G256BLTH | C28: Blue | D28: 10599 | E28: {=_xlfn.XLOOKUP(B28,Stock1!F:F,Stock1!J:J,"")} | F28: {=_xlfn.XLOOKUP(B28,Stock2!F:F,Stock2!J:J,"")} | G28: 1600 | H28: =D28-G28 -> 8999 | P28: 0.1 | Q28: =ROUNDUP(D28-(D28*0.1),0) -> 9540
B29: F-A175G256BKTH | C29: Black | D29: 10599 | E29: {=_xlfn.XLOOKUP(B29,Stock1!F:F,Stock1!J:J,"")} | F29: {=_xlfn.XLOOKUP(B29,Stock2!F:F,Stock2!J:J,"")} | G29: 1600 | H29: =D29-G29 -> 8999 | P29: 0.1 | Q29: =ROUNDUP(D29-(D29*0.1),0) -> 9540
A30: Galaxy A27 5G 8/128GB | B30: SM-A276BLIGTHL | C30: LIGHT PINK | D30: 10999 | E30: {=_xlfn.XLOOKUP(B30,Stock1!F:F,Stock1!J:J,"")} -> 5 | F30: {=_xlfn.XLOOKUP(B30,Stock2!F:F,Stock2!J:J,"")} -> 2 | I30: 05 แถม ไมโครเวฟ 23ลิตร มูลค่า 3,990 | J30: 1000 | K30: =D30-J30 -> 9999 | L30: 01 *ร่วม SF+
B31: SM-A276BZKGTHL | C31: Black | D31: 10999 | E31: {=_xlfn.XLOOKUP(B31,Stock1!F:F,Stock1!J:J,"")} -> 4 | F31: {=_xlfn.XLOOKUP(B31,Stock2!F:F,Stock2!J:J,"")} -> 8 | J31: 1000 | K31: =D31-J31 -> 9999
A32: Galaxy A37 5G 8/256GB | B32: SM-A376BDGTTHL | C32: Dark Green | D32: 13999 | E32: {=_xlfn.XLOOKUP(B32,Stock1!F:F,Stock1!J:J,"")} -> 3 | F32: {=_xlfn.XLOOKUP(B32,Stock2!F:F,Stock2!J:J,"")} -> 3 | I32: ดาวน์ไม่เกิน 5% | P32: 0.04 | Q32: =ROUNDUP(D32-(D32*0.04),0) -> 13440 | R32: ไม่ร่วม SF+ Cap Down
B33: SM-A376BLVTTHL | C33: Light Violet | D33: 13999 | E33: {=_xlfn.XLOOKUP(B33,Stock1!F:F,Stock1!J:J,"")} -> 3 | F33: {=_xlfn.XLOOKUP(B33,Stock2!F:F,Stock2!J:J,"")} -> 3 | P33: 0.04 | Q33: =ROUNDUP(D33-(D33*0.04),0) -> 13440
B34: SM-A376BZATTHL | C34: Gray | D34: 13999 | E34: {=_xlfn.XLOOKUP(B34,Stock1!F:F,Stock1!J:J,"")} -> 4 | F34: {=_xlfn.XLOOKUP(B34,Stock2!F:F,Stock2!J:J,"")} -> 4 | P34: 0.04 | Q34: =ROUNDUP(D34-(D34*0.04),0) -> 13440
A35: Galaxy A57 5G 8/256GB | B35: SM-A576BDBSTHL | C35: Dark Blue | D35: 16999 | E35: {=_xlfn.XLOOKUP(B35,Stock1!F:F,Stock1!J:J,"")} -> 3 | F35: {=_xlfn.XLOOKUP(B35,Stock2!F:F,Stock2!J:J,"")} -> 2 | I35: ดาวน์ไม่เกิน 5% | J35: 2000 | K35: =D35-J35 -> 14999 | L35: 01 *ไม่ร่วม SF+ | P35: 0.15 | Q35: =ROUNDUP(D35-(D35*0.15),0) -> 14450
B36: SM-A576BZVSTHL | C36: Violet | D36: 16999 | E36: {=_xlfn.XLOOKUP(B36,Stock1!F:F,Stock1!J:J,"")} | F36: {=_xlfn.XLOOKUP(B36,Stock2!F:F,Stock2!J:J,"")} -> 3 | J36: 2000 | K36: =D36-J36 -> 14999 | P36: 0.15 | Q36: =ROUNDUP(D36-(D36*0.15),0) -> 14450
B37: SM-A576BZASTHL | C37: Gray | D37: 16999 | E37: {=_xlfn.XLOOKUP(B37,Stock1!F:F,Stock1!J:J,"")} -> 2 | F37: {=_xlfn.XLOOKUP(B37,Stock2!F:F,Stock2!J:J,"")} -> 1 | J37: 2000 | K37: =D37-J37 -> 14999 | P37: 0.15 | Q37: =ROUNDUP(D37-(D37*0.15),0) -> 14450
A38: Galaxy A57 5G 12/256GB | B38: SM-A576BDBTTHL | C38: Dark Blue | D38: 17999 | E38: {=_xlfn.XLOOKUP(B38,Stock1!F:F,Stock1!J:J,"")} -> 5 | F38: {=_xlfn.XLOOKUP(B38,Stock2!F:F,Stock2!J:J,"")} -> 5 | I38: ดาวน์ไม่เกิน 7% | J38: 2000 | K38: =D38-J38 -> 15999 | P38: 0.14 | Q38: =ROUNDUP(D38-(D38*0.14),0) -> 15480
B39: SM-A576BZVTTHL | C39: Violet | D39: 17999 | E39: {=_xlfn.XLOOKUP(B39,Stock1!F:F,Stock1!J:J,"")} -> 7 | F39: {=_xlfn.XLOOKUP(B39,Stock2!F:F,Stock2!J:J,"")} -> 11 | J39: 2000 | K39: =D39-J39 -> 15999 | P39: 0.14 | Q39: =ROUNDUP(D39-(D39*0.14),0) -> 15480
B40: SM-A576BZATTHL | C40: Gray | D40: 17999 | E40: {=_xlfn.XLOOKUP(B40,Stock1!F:F,Stock1!J:J,"")} -> 9 | F40: {=_xlfn.XLOOKUP(B40,Stock2!F:F,Stock2!J:J,"")} -> 15 | J40: 2000 | K40: =D40-J40 -> 15999 | P40: 0.14 | Q40: =ROUNDUP(D40-(D40*0.14),0) -> 15480
...

Sheet สำเนาของ Promotion
B1: Promotion Samsung
E2: Stock ชั้น1 | F2: Stock ชั้น2 | G2: PROMOTION | H2: ราคาหลังหักส่วนลด PROMOTION | I2: คูปอง | J2: PROMOTION | K2: ราคาหลังหักส่วนลด PROMOTION | L2: คูปอง | M2: Remark
G3: 6 Oct - 2 Nov 2025 | J3: 31 Oct - 2 Nov 2025
A4: Galaxy A06 4/64GB | B4: SM-A065FLGDTHL | C4: Light Green | D4: 3099 | E4: {=_xlfn.XLOOKUP(B4,Stock1!F:F,Stock1!J:J,"")} | F4: {=_xlfn.XLOOKUP(B4,Stock2!F:F,Stock2!J:J,"")} | I4: 01
B5: SM-A065FZKDTHL | C5: Black | D5: 3099 | E5: {=_xlfn.XLOOKUP(B5,Stock1!F:F,Stock1!J:J,"")} | F5: {=_xlfn.XLOOKUP(B5,Stock2!F:F,Stock2!J:J,"")}
A6: Galaxy A06 4/128GB | B6: SM-A065FLGGTHL | C6: Light Green | D6: 3999 | E6: {=_xlfn.XLOOKUP(B6,Stock1!F:F,Stock1!J:J,"")} | F6: {=_xlfn.XLOOKUP(B6,Stock2!F:F,Stock2!J:J,"")} | G6: 700 | H6: =D6-G6 -> 3299
B7: SM-A065FZKGTHL | C7: Black | D7: 3999 | E7: {=_xlfn.XLOOKUP(B7,Stock1!F:F,Stock1!J:J,"")} | F7: {=_xlfn.XLOOKUP(B7,Stock2!F:F,Stock2!J:J,"")} | G7: 700 | H7: =D7-G7 -> 3299
A8: Galaxy A07 4/64GB - BOM SET | B8: F-A074G064VDTH | C8: Light Violet | D8: 2999 | E8: {=_xlfn.XLOOKUP(B8,Stock1!F:F,Stock1!J:J,"")} | F8: {=_xlfn.XLOOKUP(B8,Stock2!F:F,Stock2!J:J,"")}
B9: F-A074G064KDTH | C9: Black | D9: 2999 | E9: {=_xlfn.XLOOKUP(B9,Stock1!F:F,Stock1!J:J,"")} | F9: {=_xlfn.XLOOKUP(B9,Stock2!F:F,Stock2!J:J,"")}
A10: Galaxy A07 4/128GB - BOM SET | B10: F-A074G128VGTH | C10: Light Violet | D10: 3999 | E10: {=_xlfn.XLOOKUP(B10,Stock1!F:F,Stock1!J:J,"")} | F10: {=_xlfn.XLOOKUP(B10,Stock2!F:F,Stock2!J:J,"")}
B11: F-A074G128KGTH | C11: Black | D11: 3999 | E11: {=_xlfn.XLOOKUP(B11,Stock1!F:F,Stock1!J:J,"")} | F11: {=_xlfn.XLOOKUP(B11,Stock2!F:F,Stock2!J:J,"")}
A12: Galaxy A06 5G 6/128GB - BOM SET | B12: F-A066G8OFADTH | C12: Light Green | D12: 4499 | E12: {=_xlfn.XLOOKUP(B12,Stock1!F:F,Stock1!J:J,"")} | F12: {=_xlfn.XLOOKUP(B12,Stock2!F:F,Stock2!J:J,"")} | G12: 500 | H12: =D12-G12 -> 3999 | I12: 01
B13: F-A066K8OFADTH | C13: Black | D13: 4499 | E13: {=_xlfn.XLOOKUP(B13,Stock1!F:F,Stock1!J:J,"")} | F13: {=_xlfn.XLOOKUP(B13,Stock2!F:F,Stock2!J:J,"")} | G13: 500 | H13: =D13-G13 -> 3999
A14: Galaxy A06 5G 6/128GB | B14: SM-A066BLGHTHL | C14: Light Green | D14: 5499 | E14: {=_xlfn.XLOOKUP(B14,Stock1!F:F,Stock1!J:J,"")} | F14: {=_xlfn.XLOOKUP(B14,Stock2!F:F,Stock2!J:J,"")} | G14: 1500 | H14: =D14-G14 -> 3999
B15: SM-A066BZKHTHL | C15: Black | D15: 5499 | E15: {=_xlfn.XLOOKUP(B15,Stock1!F:F,Stock1!J:J,"")} | F15: {=_xlfn.XLOOKUP(B15,Stock2!F:F,Stock2!J:J,"")} | G15: 1500 | H15: =D15-G15 -> 3999
A16: Galaxy A16 LTE 8/256 GB | B16: SM-A165FLGITHL | C16: Light Green | D16: 6999 | E16: {=_xlfn.XLOOKUP(B16,Stock1!F:F,Stock1!J:J,"")} | F16: {=_xlfn.XLOOKUP(B16,Stock2!F:F,Stock2!J:J,"")} | G16: 1500 | H16: =D16-G16 -> 5499
B17: SM-A165FZKITHL | C17: Black | D17: 6999 | E17: {=_xlfn.XLOOKUP(B17,Stock1!F:F,Stock1!J:J,"")} | F17: {=_xlfn.XLOOKUP(B17,Stock2!F:F,Stock2!J:J,"")} | G17: 1500 | H17: =D17-G17 -> 5499
A18: Galaxy A16 5G 4/128 GB - BOM SET | B18: F-A166K128OATH | C18: Black | D18: 4999 | E18: {=_xlfn.XLOOKUP(B18,Stock1!F:F,Stock1!J:J,"")} | F18: {=_xlfn.XLOOKUP(B18,Stock2!F:F,Stock2!J:J,"")}
A19: Galaxy A16 5G 4/128 GB | B19: SM-A166PLGDTHL | C19: Light Green | D19: 5999 | E19: {=_xlfn.XLOOKUP(B19,Stock1!F:F,Stock1!J:J,"")} | F19: {=_xlfn.XLOOKUP(B19,Stock2!F:F,Stock2!J:J,"")} | G19: 1500 | H19: =D19-G19 -> 4499
B20: SM-A166PZKDTHL | C20: Black | D20: 5999 | E20: {=_xlfn.XLOOKUP(B20,Stock1!F:F,Stock1!J:J,"")} | F20: {=_xlfn.XLOOKUP(B20,Stock2!F:F,Stock2!J:J,"")} | G20: 1500 | H20: =D20-G20 -> 4499
A21: Galaxy A16 5G 8/256 GB - BOM SET | B21: F-A166G256OATH | C21: Light Green | D21: 6999 | E21: {=_xlfn.XLOOKUP(B21,Stock1!F:F,Stock1!J:J,"")} | F21: {=_xlfn.XLOOKUP(B21,Stock2!F:F,Stock2!J:J,"")}
B22: F-A166K256OATH | C22: Black | D22: 6999 | E22: {=_xlfn.XLOOKUP(B22,Stock1!F:F,Stock1!J:J,"")} | F22: {=_xlfn.XLOOKUP(B22,Stock2!F:F,Stock2!J:J,"")}
A23: Galaxy A16 5G 8/256 GB | B23: SM-A166PLGITHL | C23: Light Green | D23: 8499 | E23: {=_xlfn.XLOOKUP(B23,Stock1!F:F,Stock1!J:J,"")} | F23: {=_xlfn.XLOOKUP(B23,Stock2!F:F,Stock2!J:J,"")} | G23: 1500 | H23: =D23-G23 -> 6999
B24: SM-A166PZKITHL | C24: Black | D24: 8499 | E24: {=_xlfn.XLOOKUP(B24,Stock1!F:F,Stock1!J:J,"")} | F24: {=_xlfn.XLOOKUP(B24,Stock2!F:F,Stock2!J:J,"")} | G24: 1500 | H24: =D24-G24 -> 6999
A25: Galaxy A17 LTE 8/128 GB | B25: F-A174G128BDTH | C25: Light Blue | D25: 5999 | E25: {=_xlfn.XLOOKUP(B25,Stock1!F:F,Stock1!J:J,"")} | F25: {=_xlfn.XLOOKUP(B25,Stock2!F:F,Stock2!J:J,"")} | G25: 500 | H25: =D25-G25 -> 5499
B26: F-A174G128KDTH | C26: Black | D26: 5999 | E26: {=_xlfn.XLOOKUP(B26,Stock1!F:F,Stock1!J:J,"")} | F26: {=_xlfn.XLOOKUP(B26,Stock2!F:F,Stock2!J:J,"")} | G26: 500 | H26: =D26-G26 -> 5499
A27: Galaxy A17 5G 8/128 GB | B27: SM-A176BZBJTHL | C27: Blue | D27: 7499 | E27: {=_xlfn.XLOOKUP(B27,Stock1!F:F,Stock1!J:J,"")} -> 3 | F27: {=_xlfn.XLOOKUP(B27,Stock2!F:F,Stock2!J:J,"")} -> 6 | G27: 500 | H27: =D27-G27 -> 6999
B28: SM-A176BZKJTHL | C28: Black | D28: 7499 | E28: {=_xlfn.XLOOKUP(B28,Stock1!F:F,Stock1!J:J,"")} -> 7 | F28: {=_xlfn.XLOOKUP(B28,Stock2!F:F,Stock2!J:J,"")} -> 7 | G28: 500 | H28: =D28-G28 -> 6999
B29: F-A175G128BLTH | C29: Blue | D29: 7499 | E29: {=_xlfn.XLOOKUP(B29,Stock1!F:F,Stock1!J:J,"")} | F29: {=_xlfn.XLOOKUP(B29,Stock2!F:F,Stock2!J:J,"")} | G29: 500 | H29: =D29-G29 -> 6999
B30: F-A175G128BKTH | C30: Black | D30: 7499 | E30: {=_xlfn.XLOOKUP(B30,Stock1!F:F,Stock1!J:J,"")} | F30: {=_xlfn.XLOOKUP(B30,Stock2!F:F,Stock2!J:J,"")} | G30: 500 | H30: =D30-G30 -> 6999
A31: Galaxy A17 5G 8/256 GB | B31: SM-A176BZKKTHL | C31: Black | D31: 8999 | E31: {=_xlfn.XLOOKUP(B31,Stock1!F:F,Stock1!J:J,"")} -> 2 | F31: {=_xlfn.XLOOKUP(B31,Stock2!F:F,Stock2!J:J,"")} -> 4 | G31: 1000 | H31: =D31-G31 -> 7999
B32: F-A175G256BLTH | C32: Blue | D32: 8999 | E32: {=_xlfn.XLOOKUP(B32,Stock1!F:F,Stock1!J:J,"")} | F32: {=_xlfn.XLOOKUP(B32,Stock2!F:F,Stock2!J:J,"")} | G32: 1000 | H32: =D32-G32 -> 7999
B33: F-A175G256BKTH | C33: Black | D33: 8999 | E33: {=_xlfn.XLOOKUP(B33,Stock1!F:F,Stock1!J:J,"")} | F33: {=_xlfn.XLOOKUP(B33,Stock2!F:F,Stock2!J:J,"")} | G33: 1000 | H33: =D33-G33 -> 7999
A34: Galaxy A26 5G 8/256GB | B34: SM-A266BZKHTHL | C34: Black | D34: 10999 | E34: {=_xlfn.XLOOKUP(B34,Stock1!F:F,Stock1!J:J,"")} | F34: {=_xlfn.XLOOKUP(B34,Stock2!F:F,Stock2!J:J,"")} | G34: 1000 | H34: =D34-G34 -> 9999 | I34: 01
B35: SM-A266BLGHTHL | C35: Light Green | D35: 10999 | E35: {=_xlfn.XLOOKUP(B35,Stock1!F:F,Stock1!J:J,"")} | F35: {=_xlfn.XLOOKUP(B35,Stock2!F:F,Stock2!J:J,"")} | G35: 1000 | H35: =D35-G35 -> 9999
A36: Galaxy A36 5G 8/128GB | B36: SM-A366BLGSTHL | C36: Light Green | D36: 11999 | E36: {=_xlfn.XLOOKUP(B36,Stock1!F:F,Stock1!J:J,"")} | F36: {=_xlfn.XLOOKUP(B36,Stock2!F:F,Stock2!J:J,"")} | G36: 800 | H36: =D36-G36 -> 11199 | M36: ไม่ร่วม Finance
B37: SM-A366BLVSTHL | C37: Light Violet | D37: 11999 | E37: {=_xlfn.XLOOKUP(B37,Stock1!F:F,Stock1!J:J,"")} | F37: {=_xlfn.XLOOKUP(B37,Stock2!F:F,Stock2!J:J,"")} | G37: 800 | H37: =D37-G37 -> 11199
B38: SM-A366BZKSTHL | C38: Black | D38: 11999 | E38: {=_xlfn.XLOOKUP(B38,Stock1!F:F,Stock1!J:J,"")} | F38: {=_xlfn.XLOOKUP(B38,Stock2!F:F,Stock2!J:J,"")} | G38: 800 | H38: =D38-G38 -> 11199
A39: Galaxy A56 5G 8/128GB | B39: SM-A566BLISTHL | C39: Light Pink | D39: 13999 | E39: {=_xlfn.XLOOKUP(B39,Stock1!F:F,Stock1!J:J,"")} | F39: {=_xlfn.XLOOKUP(B39,Stock2!F:F,Stock2!J:J,"")} | G39: 1000 | H39: =D39-G39 -> 12999
B40: SM-A566BZGSTHL | C40: GREEN | D40: 13999 | E40: {=_xlfn.XLOOKUP(B40,Stock1!F:F,Stock1!J:J,"")} | F40: {=_xlfn.XLOOKUP(B40,Stock2!F:F,Stock2!J:J,"")} | G40: 1000 | H40: =D40-G40 -> 12999
...

Sheet ชีต61

Sheet SES Student Campaign
A2: Student Promotion model list for SES & SPS
A3: Period: 01 Jun - 05 Jul 2026
A4: Model Name | B4: ราคาเต็ม | C4: ราคา Student | D4: % ส่วนลด | E4: ราคาโปรกลาง | F4: ส่วนต่าง STD VS NTW | G4: Remarks
A5: Mobile: A-Series
A6: Galaxy A07 LTE (4/64) | B6: 3299 | C6: 2969 | D6: 0.1 | E6: 3299 | F6: 330
A7: Galaxy A07 LTE (4/128) | B7: 3999 | C7: 3599 | D7: 0.1 | E7: 3999 | F7: 400
A8: Galaxy A07 5G (6/128) | B8: 5999 | C8: 5399 | D8: 0.1 | E8: 5999 | F8: 600 | G8: ใช้ร่วมกับ SF+ ดาวน์ไม่เกิน 20% ได้เฉพาะ UPC เท่านั้น
A9: Galaxy A17 5G (8/128) | B9: 7499 | C9: 6749 | D9: 0.1 | E9: 7499 | F9: 750
A10: Galaxy A17 5G (8/256) | B10: 8999 | C10: 8099 | D10: 0.1 | E10: 8999 | F10: 900
A11: Galaxy A37 5G (8/256) | B11: 13999 | C11: 12599 | D11: 0.1 | E11: 13999 | F11: 1400 | G11: ใช้ร่วม SF+ ดาวน์ไม่เกิน 10% ได้
A12: Galaxy A57 5G (8/256) | B12: 16999 | C12: 15299 | D12: 0.1 | E12: 15999 | F12: 700
A13: Galaxy A57 5G (12/256) | B13: 17999 | C13: 16199 | D13: 0.1 | E13: 16999 | F13: 800
A14: Galaxy A57 5G (12/512) | B14: 20999 | C14: 18899 | D14: 0.1 | E14: 19999 | F14: 1100
A15: Mobile: S-Series
A16: Galaxy S25 FE (12/128) | B16: 22900 | C16: 19465 | D16: 0.15 | E16: 21900 | F16: 2435 | G16: ใช้ร่วม SF+ ดาวน์ไม่เกิน 10% ได้
A17: Galaxy S25 FE (12/256) | B17: 26900 | C17: 22865 | D17: 0.15 | E17: 24900 | F17: 2035
A18: Galaxy S26 Ultra (12/256) | B18: 46900 | C18: 42210 | D18: 0.1 | E18: 44900 | F18: 2690 | G18: ใช้ร่วม SF+ ดาวน์ไม่เกิน 20% ได้
A19: Galaxy S26+ (12/256) | B19: 40900 | C19: 36810 | D19: 0.1 | E19: 38900 | F19: 2090 | G19: ใช้ร่วม SF+ ดาวน์ไม่เกิน 10% ได้
A20: Galaxy S26 (12/256) | B20: 33900 | C20: 30510 | D20: 0.1 | E20: 31900 | F20: 1390
A21: Mobile: Z-Series
A22: Galaxy Z Flip7 (12/256) | B22: 40900 | C22: 34765 | D22: 0.15 | E22: 36900 | F22: 2135 | G22: ใช้ร่วม SF+ ดาวน์ไม่เกิน 10% ได้
A23: Galaxy Z Flip7 (12/512) | B23: 48900 | C23: 41565 | D23: 0.15 | E23: 44900 | F23: 3335
A24: Tablet: A
A25: Galaxy Tab A11 LTE (8/128) | B25: 7490 | C25: 6367 | D25: 0.15 | E25: 6990 | F25: 624 | G25: ไม่สามารถใช้ร่วมกับ SF+ ดาวน์ไม่เกิน 10% ได้ แลกซื้อ Keyboard / Book Cover ลด 50%
A26: Galaxy Tab A11+ Wifi (6/128) | B26: 8490 | C26: 7217 | D26: 0.15 | E26: 7990 | F26: 774
A27: Galaxy Tab A11+ 5G (6/128) | B27: 10490 | C27: 8917 | D27: 0.15 | E27: 9990 | F27: 1074
A28: Tablet: Lite
A29: Galaxy Tab S10 Lite Wi-Fi | B29: 12990 | C29: 11691 | D29: 0.1 | E29: 12990 | F29: 1299 | G29: ฟรี Keyboard Cover (1,990) GP-FCX400RLABH
A30: Galaxy Tab S10 Lite 5G | B30: 16990 | C30: 15291 | D30: 0.1 | E30: 16990 | F30: 1699
A31: Tablet: FE
A32: Galaxy Tab S10 FE Wi-Fi | B32: 19900 | C32: 16915 | D32: 0.15 | E32: 17900 | F32: 985 | G32: แลกซื้อ Keyboard / Book Cover ลด 50%
A33: Galaxy Tab S10 FE 5G | B33: 22900 | C33: 19465 | D33: 0.15 | E33: 20900 | F33: 1435
A34: Galaxy Tab S10 FE+ WiFi | B34: 27900 | C34: 23715 | D34: 0.15 | E34: 23900 | F34: 185
A35: Galaxy Tab S10 FE+ 5G | B35: 30900 | C35: 26265 | D35: 0.15 | E35: 26900 | F35: 635
A36: Tablet: S
A37: Galaxy Tab S11 Wi-Fi | B37: 28900 | C37: 24565 | D37: 0.15 | E37: 26900 | F37: 2335 | G37: แลกซื้อ Keyboard / Book Cover ลด 50%
A38: Galaxy Tab S11 5G | B38: 33900 | C38: 28815 | D38: 0.15 | E38: 31900 | F38: 3085
A39: Galaxy Tab S11 Ultra 5G | B39: 48900 | C39: 41565 | D39: 0.15 | E39: 45900 | F39: 4335

Sheet ของแถม
A1: SM88592896555607 | B1: Model Code | D1: "RRP In.vat" | E1: Stock ชั้น1 | F1: Stock จริง | M1: หมายเหตุ | N1: จำนวน | O1: ขาด/เกิน | X1: {=_xlfn.XLOOKUP("Other",Stock1!A1,Stock1!I1,"")} | Y1: {=_xlfn.XLOOKUP(X1,Stock1!I1,Stock1!F1,"")} | Z1: {=_xlfn.XLOOKUP(X1,Stock1!I1,Stock1!J1,"")} | AA1: {=_xlfn.XLOOKUP(Y1,DATAPremium!A:A,DATAPremium!C:C,"")}
A2: =UNIQUE(X:X) | B2: =UNIQUE(Y:Y) | X2: {=_xlfn.XLOOKUP("Other",Stock1!A2,Stock1!I2,"")} | Y2: {=_xlfn.XLOOKUP(X2,Stock1!I2,Stock1!F2,"")} | Z2: {=_xlfn.XLOOKUP(X2,Stock1!I2,Stock1!J2,"")} | AA2: {=_xlfn.XLOOKUP(Y2,DATAPremium!A:A,DATAPremium!C:C,"")}
A3: [PM] Double Wall Stainless Steel 600ml | B3: 6931481215710 | C3: {=_xlfn.XLOOKUP(B3,DATAPremium!A:A,DATAPremium!C:C,"")} -> Tablet | D3: {=_xlfn.XLOOKUP(B3,Stock1!F:F,Stock1!E:E,"")} -> 299 | E3: {=_xlfn.XLOOKUP(B3,Stock1!F:F,Stock1!J:J,"")} -> 16 | F3: 15 | N3: =F3-E3 -> -1 | X3: {=_xlfn.XLOOKUP("Other",Stock1!A3,Stock1!I3,"")} | Y3: {=_xlfn.XLOOKUP(X3,Stock1!I3,Stock1!F3,"")} | Z3: {=_xlfn.XLOOKUP(X3,Stock1!I3,Stock1!J3,"")} | AA3: {=_xlfn.XLOOKUP(Y3,DATAPremium!A:A,DATAPremium!C:C,"")}
A4: Premium D-Power M22 Speaker Bluetooth | B4: 8859289657762 | C4: {=_xlfn.XLOOKUP(B4,DATAPremium!A:A,DATAPremium!C:C,"")} -> Smartphone 10,000 up | D4: {=_xlfn.XLOOKUP(B4,Stock1!F:F,Stock1!E:E,"")} -> 599 | E4: {=_xlfn.XLOOKUP(B4,Stock1!F:F,Stock1!J:J,"")} -> 19 | F4: 19 | N4: =F4-E4 -> 0 | X4: {=_xlfn.XLOOKUP("Other",Stock1!A4,Stock1!I4,"")} | Y4: {=_xlfn.XLOOKUP(X4,Stock1!I4,Stock1!F4,"")} | Z4: {=_xlfn.XLOOKUP(X4,Stock1!I4,Stock1!J4,"")} | AA4: {=_xlfn.XLOOKUP(Y4,DATAPremium!A:A,DATAPremium!C:C,"")}
A5: Premium SAMSUNG TC-04 (Type-C) | B5: 8859289665477 | C5: {=_xlfn.XLOOKUP(B5,DATAPremium!A:A,DATAPremium!C:C,"")} -> Smartphone | D5: {=_xlfn.XLOOKUP(B5,Stock1!F:F,Stock1!E:E,"")} -> 399 | E5: {=_xlfn.XLOOKUP(B5,Stock1!F:F,Stock1!J:J,"")} -> 18 | F5: 19 | N5: =F5-E5 -> 1 | X5: {=_xlfn.XLOOKUP("Other",Stock1!A5,Stock1!I5,"")} | Y5: {=_xlfn.XLOOKUP(X5,Stock1!I5,Stock1!F5,"")} | Z5: {=_xlfn.XLOOKUP(X5,Stock1!I5,Stock1!J5,"")} | AA5: {=_xlfn.XLOOKUP(Y5,DATAPremium!A:A,DATAPremium!C:C,"")}
A6: [PM] Phone Stand First class NO V168 Phoenix | B6: 8859763200989 | C6: {=_xlfn.XLOOKUP(B6,DATAPremium!A:A,DATAPremium!C:C,"")} -> Tablet | D6: {=_xlfn.XLOOKUP(B6,Stock1!F:F,Stock1!E:E,"")} -> 199 | E6: {=_xlfn.XLOOKUP(B6,Stock1!F:F,Stock1!J:J,"")} -> 20 | F6: 20 | N6: =F6-E6 -> 0 | X6: {=_xlfn.XLOOKUP("Other",Stock1!A6,Stock1!I6,"")} | Y6: {=_xlfn.XLOOKUP(X6,Stock1!I6,Stock1!F6,"")} | Z6: {=_xlfn.XLOOKUP(X6,Stock1!I6,Stock1!J6,"")} | AA6: {=_xlfn.XLOOKUP(Y6,DATAPremium!A:A,DATAPremium!C:C,"")}
A7: [Premium] Gaabor weighing scale GWS-M01A - Black | B7: PM4897121002558 | C7: {=_xlfn.XLOOKUP(B7,DATAPremium!A:A,DATAPremium!C:C,"")} | D7: {=_xlfn.XLOOKUP(B7,Stock1!F:F,Stock1!E:E,"")} -> 599 | E7: {=_xlfn.XLOOKUP(B7,Stock1!F:F,Stock1!J:J,"")} -> 3 | F7: 5 | N7: =F7-E7 -> 2 | X7: {=_xlfn.XLOOKUP("Other",Stock1!A7,Stock1!I7,"")} | Y7: {=_xlfn.XLOOKUP(X7,Stock1!I7,Stock1!F7,"")} | Z7: {=_xlfn.XLOOKUP(X7,Stock1!I7,Stock1!J7,"")} | AA7: {=_xlfn.XLOOKUP(Y7,DATAPremium!A:A,DATAPremium!C:C,"")}
A8: [Premium] Gaabor Air Fryer 4L AF-40M01A | B8: PM4897121009793 | C8: {=_xlfn.XLOOKUP(B8,DATAPremium!A:A,DATAPremium!C:C,"")} -> Smartphone 20,000 up | D8: {=_xlfn.XLOOKUP(B8,Stock1!F:F,Stock1!E:E,"")} -> 999 | E8: {=_xlfn.XLOOKUP(B8,Stock1!F:F,Stock1!J:J,"")} -> 27 | F8: 30 | N8: =F8-E8 -> 3 | X8: {=_xlfn.XLOOKUP("Other",Stock1!A8,Stock1!I8,"")} | Y8: {=_xlfn.XLOOKUP(X8,Stock1!I8,Stock1!F8,"")} | Z8: {=_xlfn.XLOOKUP(X8,Stock1!I8,Stock1!J8,"")} | AA8: {=_xlfn.XLOOKUP(Y8,DATAPremium!A:A,DATAPremium!C:C,"")}
A9: Premiun ����Ѻ�� Mini YOUMI-SAMSUNG | B9: PM6931481215697 | C9: {=_xlfn.XLOOKUP(B9,DATAPremium!A:A,DATAPremium!C:C,"")} -> Smartphone 10,000 up | D9: {=_xlfn.XLOOKUP(B9,Stock1!F:F,Stock1!E:E,"")} -> 359 | E9: {=_xlfn.XLOOKUP(B9,Stock1!F:F,Stock1!J:J,"")} -> 51 | F9: 51 | N9: =F9-E9 -> 0 | X9: {=_xlfn.XLOOKUP("Other",Stock1!A9,Stock1!I9,"")} | Y9: {=_xlfn.XLOOKUP(X9,Stock1!I9,Stock1!F9,"")} | Z9: {=_xlfn.XLOOKUP(X9,Stock1!I9,Stock1!J9,"")} | AA9: {=_xlfn.XLOOKUP(Y9,DATAPremium!A:A,DATAPremium!C:C,"")}
A10: Premium Robot Portable handheld fan RT-HF01 - White | B10: PM6936678491526 | C10: {=_xlfn.XLOOKUP(B10,DATAPremium!A:A,DATAPremium!C:C,"")} -> Smartphone 5,000 up | D10: {=_xlfn.XLOOKUP(B10,Stock1!F:F,Stock1!E:E,"")} -> 399 | E10: {=_xlfn.XLOOKUP(B10,Stock1!F:F,Stock1!J:J,"")} -> 6 | F10: 6 | N10: =F10-E10 -> 0 | X10: {=_xlfn.XLOOKUP("Other",Stock1!A10,Stock1!I10,"")} | Y10: {=_xlfn.XLOOKUP(X10,Stock1!I10,Stock1!F10,"")} | Z10: {=_xlfn.XLOOKUP(X10,Stock1!I10,Stock1!J10,"")} | AA10: {=_xlfn.XLOOKUP(Y10,DATAPremium!A:A,DATAPremium!C:C,"")}
A11: Premium D-Power Blackpack-SAMSUNG | B11: PM8859289684768 | C11: {=_xlfn.XLOOKUP(B11,DATAPremium!A:A,DATAPremium!C:C,"")} -> Smartphone 8,000 up | D11: {=_xlfn.XLOOKUP(B11,Stock1!F:F,Stock1!E:E,"")} -> 599 | E11: {=_xlfn.XLOOKUP(B11,Stock1!F:F,Stock1!J:J,"")} -> 2 | F11: 2 | N11: =F11-E11 -> 0 | X11: {=_xlfn.XLOOKUP("Other",Stock1!A11,Stock1!I11,"")} | Y11: {=_xlfn.XLOOKUP(X11,Stock1!I11,Stock1!F11,"")} | Z11: {=_xlfn.XLOOKUP(X11,Stock1!I11,Stock1!J11,"")} | AA11: {=_xlfn.XLOOKUP(Y11,DATAPremium!A:A,DATAPremium!C:C,"")}
A12: [PM] Backpack Fashion Phoenix | B12: PREMIUM0017044 | C12: {=_xlfn.XLOOKUP(B12,DATAPremium!A:A,DATAPremium!C:C,"")} -> Tablet | D12: {=_xlfn.XLOOKUP(B12,Stock1!F:F,Stock1!E:E,"")} -> 199 | E12: {=_xlfn.XLOOKUP(B12,Stock1!F:F,Stock1!J:J,"")} -> 27 | F12: 27 | N12: =F12-E12 -> 0 | X12: {=_xlfn.XLOOKUP("Other",Stock1!A12,Stock1!I12,"")} | Y12: {=_xlfn.XLOOKUP(X12,Stock1!I12,Stock1!F12,"")} | Z12: {=_xlfn.XLOOKUP(X12,Stock1!I12,Stock1!J12,"")} | AA12: {=_xlfn.XLOOKUP(Y12,DATAPremium!A:A,DATAPremium!C:C,"")}
A13: [PM] Sling Bag Phoenix | B13: PREMIUM0017046 | C13: {=_xlfn.XLOOKUP(B13,DATAPremium!A:A,DATAPremium!C:C,"")} | D13: {=_xlfn.XLOOKUP(B13,Stock1!F:F,Stock1!E:E,"")} -> 199 | E13: {=_xlfn.XLOOKUP(B13,Stock1!F:F,Stock1!J:J,"")} -> 20 | F13: 20 | N13: =F13-E13 -> 0 | X13: {=_xlfn.XLOOKUP("Other",Stock1!A13,Stock1!I13,"")} | Y13: {=_xlfn.XLOOKUP(X13,Stock1!I13,Stock1!F13,"")} | Z13: {=_xlfn.XLOOKUP(X13,Stock1!I13,Stock1!J13,"")} | AA13: {=_xlfn.XLOOKUP(Y13,DATAPremium!A:A,DATAPremium!C:C,"")}
A14: [PM] Small Talk TC-04 TypeC Tablet | B14: PREMIUM-665477 | C14: {=_xlfn.XLOOKUP(B14,DATAPremium!A:A,DATAPremium!C:C,"")} -> Tablet | D14: {=_xlfn.XLOOKUP(B14,Stock1!F:F,Stock1!E:E,"")} -> 199 | E14: {=_xlfn.XLOOKUP(B14,Stock1!F:F,Stock1!J:J,"")} -> 27 | F14: 28 | N14: =F14-E14 -> 1 | X14: {=_xlfn.XLOOKUP("Other",Stock1!A14,Stock1!I14,"")} | Y14: {=_xlfn.XLOOKUP(X14,Stock1!I14,Stock1!F14,"")} | Z14: {=_xlfn.XLOOKUP(X14,Stock1!I14,Stock1!J14,"")} | AA14: {=_xlfn.XLOOKUP(Y14,DATAPremium!A:A,DATAPremium!C:C,"")}
... A28: Premium Samsung SmartTag2 - S26 Series | B28: Z-SMARTTAG2WMR | C28: {=_xlfn.XLOOKUP(B28,DATAPremium!A:A,DATAPremium!C:C,"")} -> Smartphone S26 Ultra | D28: {=_xlfn.XLOOKUP(B28,Stock1!F:F,Stock1!E:E,"")} -> 1090 | E28: {=_xlfn.XLOOKUP(B28,Stock1!F:F,Stock1!J:J,"")} -> 7 | F28: 7 | N28: =F28-E28 -> 0 | X28: {=_xlfn.XLOOKUP("Other",Stock1!A28,Stock1!I28,"")} | Y28: {=_xlfn.XLOOKUP(X28,Stock1!I28,Stock1!F28,"")} | Z28: {=_xlfn.XLOOKUP(X28,Stock1!I28,Stock1!J28,"")} | AA28: {=_xlfn.XLOOKUP(Y28,DATAPremium!A:A,DATAPremium!C:C,"")}
C29: {=_xlfn.XLOOKUP(B29,DATAPremium!A:A,DATAPremium!C:C,"")} | D29: {=_xlfn.XLOOKUP(B29,Stock1!F:F,Stock1!E:E,"")} | E29: {=_xlfn.XLOOKUP(B29,Stock1!F:F,Stock1!J:J,"")} | N29: =F29-E29 -> 0 | X29: {=_xlfn.XLOOKUP("Other",Stock1!A29,Stock1!I29,"")} | Y29: {=_xlfn.XLOOKUP(X29,Stock1!I29,Stock1!F29,"")} | Z29: {=_xlfn.XLOOKUP(X29,Stock1!I29,Stock1!J29,"")} | AA29: {=_xlfn.XLOOKUP(Y29,DATAPremium!A:A,DATAPremium!C:C,"")}
C30: {=_xlfn.XLOOKUP(B30,DATAPremium!A:A,DATAPremium!C:C,"")} | D30: {=_xlfn.XLOOKUP(B30,Stock1!F:F,Stock1!E:E,"")} | E30: {=_xlfn.XLOOKUP(B30,Stock1!F:F,Stock1!J:J,"")} | N30: =F30-E30 -> 0 | X30: {=_xlfn.XLOOKUP("Other",Stock1!A30,Stock1!I30,"")} | Y30: {=_xlfn.XLOOKUP(X30,Stock1!I30,Stock1!F30,"")} | Z30: {=_xlfn.XLOOKUP(X30,Stock1!I30,Stock1!J30,"")} | AA30: {=_xlfn.XLOOKUP(Y30,DATAPremium!A:A,DATAPremium!C:C,"")}
C31: {=_xlfn.XLOOKUP(B31,DATAPremium!A:A,DATAPremium!C:C,"")} | D31: {=_xlfn.XLOOKUP(B31,Stock1!F:F,Stock1!E:E,"")} | E31: {=_xlfn.XLOOKUP(B31,Stock1!F:F,Stock1!J:J,"")} | N31: =F31-E31 -> 0 | X31: {=_xlfn.XLOOKUP("Other",Stock1!A31,Stock1!I31,"")} | Y31: {=_xlfn.XLOOKUP(X31,Stock1!I31,Stock1!F31,"")} | Z31: {=_xlfn.XLOOKUP(X31,Stock1!I31,Stock1!J31,"")} | AA31: {=_xlfn.XLOOKUP(Y31,DATAPremium!A:A,DATAPremium!C:C,"")}
C32: {=_xlfn.XLOOKUP(B32,DATAPremium!A:A,DATAPremium!C:C,"")} | D32: {=_xlfn.XLOOKUP(B32,Stock1!F:F,Stock1!E:E,"")} | E32: {=_xlfn.XLOOKUP(B32,Stock1!F:F,Stock1!J:J,"")} | N32: =F32-E32 -> 0 | X32: {=_xlfn.XLOOKUP("Other",Stock1!A32,Stock1!I32,"")} | Y32: {=_xlfn.XLOOKUP(X32,Stock1!I32,Stock1!F32,"")} | Z32: {=_xlfn.XLOOKUP(X32,Stock1!I32,Stock1!J32,"")} | AA32: {=_xlfn.XLOOKUP(Y32,DATAPremium!A:A,DATAPremium!C:C,"")}
C33: {=_xlfn.XLOOKUP(B33,DATAPremium!A:A,DATAPremium!C:C,"")} | D33: {=_xlfn.XLOOKUP(B33,Stock1!F:F,Stock1!E:E,"")} | E33: {=_xlfn.XLOOKUP(B33,Stock1!F:F,Stock1!J:J,"")} | N33: =F33-E33 -> 0 | X33: {=_xlfn.XLOOKUP("Other",Stock1!A33,Stock1!I33,"")} | Y33: {=_xlfn.XLOOKUP(X33,Stock1!I33,Stock1!F33,"")} | Z33: {=_xlfn.XLOOKUP(X33,Stock1!I33,Stock1!J33,"")} | AA33: {=_xlfn.XLOOKUP(Y33,DATAPremium!A:A,DATAPremium!C:C,"")}
C34: {=_xlfn.XLOOKUP(B34,DATAPremium!A:A,DATAPremium!C:C,"")} | D34: {=_xlfn.XLOOKUP(B34,Stock1!F:F,Stock1!E:E,"")} | E34: {=_xlfn.XLOOKUP(B34,Stock1!F:F,Stock1!J:J,"")} | N34: =F34-E34 -> 0 | X34: {=_xlfn.XLOOKUP("Other",Stock1!A34,Stock1!I34,"")} | Y34: {=_xlfn.XLOOKUP(X34,Stock1!I34,Stock1!F34,"")} | Z34: {=_xlfn.XLOOKUP(X34,Stock1!I34,Stock1!J34,"")} | AA34: {=_xlfn.XLOOKUP(Y34,DATAPremium!A:A,DATAPremium!C:C,"")}
C35: {=_xlfn.XLOOKUP(B35,DATAPremium!A:A,DATAPremium!C:C,"")} | D35: {=_xlfn.XLOOKUP(B35,Stock1!F:F,Stock1!E:E,"")} | E35: {=_xlfn.XLOOKUP(B35,Stock1!F:F,Stock1!J:J,"")} | N35: =F35-E35 -> 0 | X35: {=_xlfn.XLOOKUP("Other",Stock1!A35,Stock1!I35,"")} | Y35: {=_xlfn.XLOOKUP(X35,Stock1!I35,Stock1!F35,"")} | Z35: {=_xlfn.XLOOKUP(X35,Stock1!I35,Stock1!J35,"")} | AA35: {=_xlfn.XLOOKUP(Y35,DATAPremium!A:A,DATAPremium!C:C,"")}
C36: {=_xlfn.XLOOKUP(B36,DATAPremium!A:A,DATAPremium!C:C,"")} | D36: {=_xlfn.XLOOKUP(B36,Stock1!F:F,Stock1!E:E,"")} | E36: {=_xlfn.XLOOKUP(B36,Stock1!F:F,Stock1!J:J,"")} | N36: =F36-E36 -> 0 | X36: {=_xlfn.XLOOKUP("Other",Stock1!A36,Stock1!I36,"")} | Y36: {=_xlfn.XLOOKUP(X36,Stock1!I36,Stock1!F36,"")} | Z36: {=_xlfn.XLOOKUP(X36,Stock1!I36,Stock1!J36,"")} | AA36: {=_xlfn.XLOOKUP(Y36,DATAPremium!A:A,DATAPremium!C:C,"")}
C37: {=_xlfn.XLOOKUP(B37,DATAPremium!A:A,DATAPremium!C:C,"")} | D37: {=_xlfn.XLOOKUP(B37,Stock1!F:F,Stock1!E:E,"")} | E37: {=_xlfn.XLOOKUP(B37,Stock1!F:F,Stock1!J:J,"")} | N37: =F37-E37 -> 0 | X37: {=_xlfn.XLOOKUP("Other",Stock1!A37,Stock1!I37,"")} | Y37: {=_xlfn.XLOOKUP(X37,Stock1!I37,Stock1!F37,"")} | Z37: {=_xlfn.XLOOKUP(X37,Stock1!I37,Stock1!J37,"")} | AA37: {=_xlfn.XLOOKUP(Y37,DATAPremium!A:A,DATAPremium!C:C,"")}
C38: {=_xlfn.XLOOKUP(B38,DATAPremium!A:A,DATAPremium!C:C,"")} | D38: {=_xlfn.XLOOKUP(B38,Stock1!F:F,Stock1!E:E,"")} | E38: {=_xlfn.XLOOKUP(B38,Stock1!F:F,Stock1!J:J,"")} | N38: =F38-E38 -> 0 | X38: {=_xlfn.XLOOKUP("Other",Stock1!A38,Stock1!I38,"")} | Y38: {=_xlfn.XLOOKUP(X38,Stock1!I38,Stock1!F38,"")} | Z38: {=_xlfn.XLOOKUP(X38,Stock1!I38,Stock1!J38,"")} | AA38: {=_xlfn.XLOOKUP(Y38,DATAPremium!A:A,DATAPremium!C:C,"")}
C39: {=_xlfn.XLOOKUP(B39,DATAPremium!A:A,DATAPremium!C:C,"")} | D39: {=_xlfn.XLOOKUP(B39,Stock1!F:F,Stock1!E:E,"")} | E39: =_xlfn.XLOOKUP(A39,X:X,Z:Z,"") | N39: =F39-E39 -> 0 | X39: {=_xlfn.XLOOKUP("Other",Stock1!A39,Stock1!I39,"")} | Y39: {=_xlfn.XLOOKUP(X39,Stock1!I39,Stock1!F39,"")} | Z39: {=_xlfn.XLOOKUP(X39,Stock1!I39,Stock1!J39,"")} | AA39: {=_xlfn.XLOOKUP(Y39,DATAPremium!A:A,DATAPremium!C:C,"")}
C40: {=_xlfn.XLOOKUP(B40,DATAPremium!A:A,DATAPremium!C:C,"")} | D40: {=_xlfn.XLOOKUP(B40,Stock1!F:F,Stock1!E:E,"")} | E40: =_xlfn.XLOOKUP(A40,X:X,Z:Z,"") | N40: =F40-E40 -> 0 | X40: {=_xlfn.XLOOKUP("Other",Stock1!A40,Stock1!I40,"")} | Y40: {=_xlfn.XLOOKUP(X40,Stock1!I40,Stock1!F40,"")} | Z40: {=_xlfn.XLOOKUP(X40,Stock1!I40,Stock1!J40,"")} | AA40: {=_xlfn.XLOOKUP(Y40,DATAPremium!A:A,DATAPremium!C:C,"")}
C41: {=_xlfn.XLOOKUP(B41,DATAPremium!A:A,DATAPremium!C:C,"")} | E41: =_xlfn.XLOOKUP(A41,X:X,Z:Z,"") | N41: =F41-E41 -> 0 | X41: {=_xlfn.XLOOKUP("Other",Stock1!A41,Stock1!I41,"")} | Y41: {=_xlfn.XLOOKUP(X41,Stock1!I41,Stock1!F41,"")} | Z41: {=_xlfn.XLOOKUP(X41,Stock1!I41,Stock1!J41,"")} | AA41: {=_xlfn.XLOOKUP(Y41,DATAPremium!A:A,DATAPremium!C:C,"")}
C42: {=_xlfn.XLOOKUP(B42,DATAPremium!A:A,DATAPremium!C:C,"")} | E42: =_xlfn.XLOOKUP(A42,X:X,Z:Z,"") | N42: =F42-E42 -> 0 | X42: {=_xlfn.XLOOKUP("Other",Stock1!A42,Stock1!I42,"")} | Y42: {=_xlfn.XLOOKUP(X42,Stock1!I42,Stock1!F42,"")} | Z42: {=_xlfn.XLOOKUP(X42,Stock1!I42,Stock1!J42,"")} | AA42: {=_xlfn.XLOOKUP(Y42,DATAPremium!A:A,DATAPremium!C:C,"")}
A43: , | C43: {=_xlfn.XLOOKUP(B43,DATAPremium!A:A,DATAPremium!C:C,"")} | E43: =_xlfn.XLOOKUP(A43,X:X,Z:Z,"") | N43: =F43-E43 -> 0 | X43: {=_xlfn.XLOOKUP("Other",Stock1!A43,Stock1!I43,"")} | Y43: {=_xlfn.XLOOKUP(X43,Stock1!I43,Stock1!F43,"")} | Z43: {=_xlfn.XLOOKUP(X43,Stock1!I43,Stock1!J43,"")} | AA43: {=_xlfn.XLOOKUP(Y43,DATAPremium!A:A,DATAPremium!C:C,"")}
C44: {=_xlfn.XLOOKUP(B44,DATAPremium!A:A,DATAPremium!C:C,"")} | E44: =_xlfn.XLOOKUP(A44,X:X,Z:Z,"") | N44: =F44-E44 -> 0 | X44: {=_xlfn.XLOOKUP("Other",Stock1!A44,Stock1!I44,"")} | Y44: {=_xlfn.XLOOKUP(X44,Stock1!I44,Stock1!F44,"")} | Z44: {=_xlfn.XLOOKUP(X44,Stock1!I44,Stock1!J44,"")} | AA44: {=_xlfn.XLOOKUP(Y44,DATAPremium!A:A,DATAPremium!C:C,"")}
C45: {=_xlfn.XLOOKUP(B45,DATAPremium!A:A,DATAPremium!C:C,"")} | E45: =_xlfn.XLOOKUP(A45,X:X,Z:Z,"") | N45: =F45-E45 -> 0 | X45: {=_xlfn.XLOOKUP("Other",Stock1!A45,Stock1!I45,"")} | Y45: {=_xlfn.XLOOKUP(X45,Stock1!I45,Stock1!F45,"")} | Z45: {=_xlfn.XLOOKUP(X45,Stock1!I45,Stock1!J45,"")} | AA45: {=_xlfn.XLOOKUP(Y45,DATAPremium!A:A,DATAPremium!C:C,"")}
C46: {=_xlfn.XLOOKUP(B46,DATAPremium!A:A,DATAPremium!C:C,"")} | E46: =_xlfn.XLOOKUP(A46,X:X,Z:Z,"") | N46: =F46-E46 -> 0 | X46: {=_xlfn.XLOOKUP("Other",Stock1!A46,Stock1!I46,"")} | Y46: {=_xlfn.XLOOKUP(X46,Stock1!I46,Stock1!F46,"")} | Z46: {=_xlfn.XLOOKUP(X46,Stock1!I46,Stock1!J46,"")} | AA46: {=_xlfn.XLOOKUP(Y46,DATAPremium!A:A,DATAPremium!C:C,"")}
C47: {=_xlfn.XLOOKUP(B47,DATAPremium!A:A,DATAPremium!C:C,"")} | E47: =_xlfn.XLOOKUP(A47,X:X,Z:Z,"") | N47: =F47-E47 -> 0 | X47: {=_xlfn.XLOOKUP("Other",Stock1!A47,Stock1!I47,"")} | Y47: {=_xlfn.XLOOKUP(X47,Stock1!I47,Stock1!F47,"")} | Z47: {=_xlfn.XLOOKUP(X47,Stock1!I47,Stock1!J47,"")} | AA47: {=_xlfn.XLOOKUP(Y47,DATAPremium!A:A,DATAPremium!C:C,"")}
X48: {=_xlfn.XLOOKUP("Other",Stock1!A48,Stock1!I48,"")} | Y48: {=_xlfn.XLOOKUP(X48,Stock1!I48,Stock1!F48,"")} | Z48: {=_xlfn.XLOOKUP(X48,Stock1!I48,Stock1!J48,"")} | AA48: {=_xlfn.XLOOKUP(Y48,DATAPremium!A:A,DATAPremium!C:C,"")}
X49: {=_xlfn.XLOOKUP("Other",Stock1!A49,Stock1!I49,"")} | Y49: {=_xlfn.XLOOKUP(X49,Stock1!I49,Stock1!F49,"")} | Z49: {=_xlfn.XLOOKUP(X49,Stock1!I49,Stock1!J49,"")} | AA49: {=_xlfn.XLOOKUP(Y49,DATAPremium!A:A,DATAPremium!C:C,"")}
X50: {=_xlfn.XLOOKUP("Other",Stock1!A50,Stock1!I50,"")} | Y50: {=_xlfn.XLOOKUP(X50,Stock1!I50,Stock1!F50,"")} | Z50: {=_xlfn.XLOOKUP(X50,Stock1!I50,Stock1!J50,"")} | AA50: {=_xlfn.XLOOKUP(Y50,DATAPremium!A:A,DATAPremium!C:C,"")}
X51: {=_xlfn.XLOOKUP("Other",Stock1!A51,Stock1!I51,"")} | Y51: {=_xlfn.XLOOKUP(X51,Stock1!I51,Stock1!F51,"")} | Z51: {=_xlfn.XLOOKUP(X51,Stock1!I51,Stock1!J51,"")} | AA51: {=_xlfn.XLOOKUP(Y51,DATAPremium!A:A,DATAPremium!C:C,"")}
X52: {=_xlfn.XLOOKUP("Other",Stock1!A52,Stock1!I52,"")} | Y52: {=_xlfn.XLOOKUP(X52,Stock1!I52,Stock1!F52,"")} | Z52: {=_xlfn.XLOOKUP(X52,Stock1!I52,Stock1!J52,"")} | AA52: {=_xlfn.XLOOKUP(Y52,DATAPremium!A:A,DATAPremium!C:C,"")}
X53: {=_xlfn.XLOOKUP("Other",Stock1!A53,Stock1!I53,"")} | Y53: {=_xlfn.XLOOKUP(X53,Stock1!I53,Stock1!F53,"")} | Z53: {=_xlfn.XLOOKUP(X53,Stock1!I53,Stock1!J53,"")} | AA53: {=_xlfn.XLOOKUP(Y53,DATAPremium!A:A,DATAPremium!C:C,"")}
...

Sheet ชีต66

Sheet Incentive
A3: Brand | B3: Part Number | C3: Model | D3: SRP | E3: Sales Staff | F3: Stock ชั้น1 | G3: Stock ชั้น2 | H3: Incentive Details
A4: PAPERLIKE | B4: 4260470099102 | C4: PAPERLIKE 2-Pack Screen Protector for iPad Pro 12.9 [2018-2022] | D4: 1390 | E4: 30 | F4: =IFERROR(VLOOKUP(B4,Stock1!F:J,5,False),"") | G4: {=_xlfn.XLOOKUP(B4,Stock2!F:F,Stock2!J:J,"")} | H4: ให้ตั้งแต่ชิ้นแรก All Channel (1-31 Aug 2025)
A5: PAPERLIKE | B5: 4260470099126 | C5: PAPERLIKE 2-Pack Screen Protector for iPad 10.2 Gen7/8/9 | D5: 1390 | E5: 30 | F5: =IFERROR(VLOOKUP(B5,Stock1!F:J,5,False),"") | G5: {=_xlfn.XLOOKUP(B5,Stock2!F:F,Stock2!J:J,"")} | H5: ให้ตั้งแต่ชิ้นแรก All Channel (1-31 Aug 2025)
A6: PAPERLIKE | B6: 4260470099300 | C6: PAPERLIKE 2-Pack Screen Protector for iPad mini G6 | D6: 1390 | E6: 30 | F6: =IFERROR(VLOOKUP(B6,Stock1!F:J,5,False),"") | G6: {=_xlfn.XLOOKUP(B6,Stock2!F:F,Stock2!J:J,"")} | H6: ให้ตั้งแต่ชิ้นแรก All Channel (1-31 Aug 2025)
F7: =IFERROR(VLOOKUP(B7,Stock1!F:J,5,False),"") | G7: {=_xlfn.XLOOKUP(B7,Stock2!F:F,Stock2!J:J,"")} | H7: ให้ตั้งแต่ชิ้นแรก All Channel (1-31 July 2025)
A8: ZAGG | B8: 840056173507 | C8: ZAGG Bundle Set for iPhone 14 Pro | D8: 2670 | E8: 70 | F8: =IFERROR(VLOOKUP(B8,Stock1!F:J,5,False),"") | G8: {=_xlfn.XLOOKUP(B8,Stock2!F:F,Stock2!J:J,"")} | H8: ให้ตั้งแต่ชิ้นแรก All Channel (1-31 Aug 2025)
A9: ZAGG | B9: 840056173514 | C9: ZAGG Bundle Set for iPhone 14 Plus | D9: 2670 | E9: 70 | F9: =IFERROR(VLOOKUP(B9,Stock1!F:J,5,False),"") | G9: {=_xlfn.XLOOKUP(B9,Stock2!F:F,Stock2!J:J,"")} | H9: ให้ตั้งแต่ชิ้นแรก All Channel (1-31 Aug 2025)
A10: ZAGG | B10: 840056173521 | C10: ZAGG Bundle Set for iPhone 14 Pro Max | D10: 2670 | E10: 70 | F10: =IFERROR(VLOOKUP(B10,Stock1!F:J,5,False),"") | G10: {=_xlfn.XLOOKUP(B10,Stock2!F:F,Stock2!J:J,"")} | H10: ให้ตั้งแต่ชิ้นแรก All Channel (1-31 Aug 2025)
A11: ZAGG | B11: 840056198531 | C11: ZAGG Bundle Set for iPhone 15 | D11: 2670 | E11: 70 | F11: =IFERROR(VLOOKUP(B11,Stock1!F:J,5,False),"") | G11: {=_xlfn.XLOOKUP(B11,Stock2!F:F,Stock2!J:J,"")} | H11: ให้ตั้งแต่ชิ้นแรก All Channel (1-31 Aug 2025)
A12: ZAGG | B12: 840056198548 | C12: ZAGG Bundle Set for iPhone 15 Plus | D12: 2670 | E12: 70 | F12: =IFERROR(VLOOKUP(B12,Stock1!F:J,5,False),"") | G12: {=_xlfn.XLOOKUP(B12,Stock2!F:F,Stock2!J:J,"")} | H12: ให้ตั้งแต่ชิ้นแรก All Channel (1-31 Aug 2025)
A13: ZAGG | B13: 840056198555 | C13: ZAGG Bundle Set for iPhone 15 Pro | D13: 2670 | E13: 70 | F13: =IFERROR(VLOOKUP(B13,Stock1!F:J,5,False),"") | G13: {=_xlfn.XLOOKUP(B13,Stock2!F:F,Stock2!J:J,"")} | H13: ให้ตั้งแต่ชิ้นแรก All Channel (1-31 Aug 2025)
A14: ZAGG | B14: 840056198562 | C14: ZAGG Bundle Set for iPhone 15 Pro Max | D14: 2670 | E14: 70 | F14: =IFERROR(VLOOKUP(B14,Stock1!F:J,5,False),"") | G14: {=_xlfn.XLOOKUP(B14,Stock2!F:F,Stock2!J:J,"")} | H14: ให้ตั้งแต่ชิ้นแรก All Channel (1-31 Aug 2025)
F15: =IFERROR(VLOOKUP(B15,Stock1!F:J,5,False),"") | G15: {=_xlfn.XLOOKUP(B15,Stock2!F:F,Stock2!J:J,"")}
A16: ZAGG | B16: 840390300744 | C16: ZAGG Pro Keys [TH] for iPad Pro 11 [2018-2022] / Air 10.9 Gen4/5 - Black/Gray | D16: 4290 | E16: 70 | F16: =IFERROR(VLOOKUP(B16,Stock1!F:J,5,False),"") | G16: {=_xlfn.XLOOKUP(B16,Stock2!F:F,Stock2!J:J,"")} | H16: ให้ตั้งแต่ชิ้นแรก All Channel (1-31 Aug 2025)
F17: =IFERROR(VLOOKUP(B17,Stock1!F:J,5,False),"") | G17: {=_xlfn.XLOOKUP(B17,Stock2!F:F,Stock2!J:J,"")}
A18: SPIGEN | B18: 8800283301953 | C18: SPIGEN Nintendo Switch 2 Slim HD - Tray X | D18: 990 | E18: 50 | F18: =IFERROR(VLOOKUP(B18,Stock1!F:J,5,False),"") | G18: {=_xlfn.XLOOKUP(B18,Stock2!F:F,Stock2!J:J,"")} | H18: ให้ตั้งแต่ชิ้นแรก All Channel (1-31 Aug 2025)
F19: =IFERROR(VLOOKUP(B19,Stock1!F:J,5,False),"") | G19: {=_xlfn.XLOOKUP(B19,Stock2!F:F,Stock2!J:J,"")}
C20: เคสและฟิล์ม iPhone16 series | F20: =IFERROR(VLOOKUP(B20,Stock1!F:J,5,False),"") | G20: {=_xlfn.XLOOKUP(B20,Stock2!F:F,Stock2!J:J,"")}
A21: ZAGG | B21: 100616206 | C21: ZAGG Bundle Set for iPhone 16 | D21: 1990 | E21: 70 | F21: =IFERROR(VLOOKUP(B21,Stock1!F:J,5,False),"") | G21: {=_xlfn.XLOOKUP(B21,Stock2!F:F,Stock2!J:J,"")} | H21: ให้ตั้งแต่ชิ้นแรก All Channel (1-31 Aug 2025)
A22: ZAGG | B22: 100616207 | C22: ZAGG Bundle Set for iPhone 16 Plus | D22: 1990 | E22: 70 | F22: =IFERROR(VLOOKUP(B22,Stock1!F:J,5,False),"") | G22: {=_xlfn.XLOOKUP(B22,Stock2!F:F,Stock2!J:J,"")} | H22: ให้ตั้งแต่ชิ้นแรก All Channel (1-31 Aug 2025)
A23: ZAGG | B23: 100616208 | C23: ZAGG Bundle Set for iPhone 16 Pro | D23: 1990 | E23: 70 | F23: =IFERROR(VLOOKUP(B23,Stock1!F:J,5,False),"") | G23: {=_xlfn.XLOOKUP(B23,Stock2!F:F,Stock2!J:J,"")} | H23: ให้ตั้งแต่ชิ้นแรก All Channel (1-31 Aug 2025)
A24: ZAGG | B24: 100616209 | C24: ZAGG Bundle Set for iPhone 16 Pro Max | D24: 1990 | E24: 70 | F24: =IFERROR(VLOOKUP(B24,Stock1!F:J,5,False),"") | G24: {=_xlfn.XLOOKUP(B24,Stock2!F:F,Stock2!J:J,"")} | H24: ให้ตั้งแต่ชิ้นแรก All Channel (1-31 Aug 2025)
F25: =IFERROR(VLOOKUP(B25,Stock1!F:J,5,False),"") | G25: {=_xlfn.XLOOKUP(B25,Stock2!F:F,Stock2!J:J,"")}
A26: PANZERGLASS | B26: S31786 | C26: PANZERGLASS Bundle Set for iPhone 16 | D26: 2490 | E26: 70 | F26: =IFERROR(VLOOKUP(B26,Stock1!F:J,5,False),"") | G26: {=_xlfn.XLOOKUP(B26,Stock2!F:F,Stock2!J:J,"")} | H26: ให้ตั้งแต่ชิ้นแรก All Channel (1-31 Aug 2025)
A27: PANZERGLASS | B27: S31788 | C27: PANZERGLASS Bundle Set for iPhone 16 Plus | D27: 2490 | E27: 70 | F27: =IFERROR(VLOOKUP(B27,Stock1!F:J,5,False),"") | G27: {=_xlfn.XLOOKUP(B27,Stock2!F:F,Stock2!J:J,"")} | H27: ให้ตั้งแต่ชิ้นแรก All Channel (1-31 Aug 2025)
A28: PANZERGLASS | B28: S31787 | C28: PANZERGLASS Bundle Set for iPhone 16 Pro | D28: 2490 | E28: 70 | F28: =IFERROR(VLOOKUP(B28,Stock1!F:J,5,False),"") | G28: {=_xlfn.XLOOKUP(B28,Stock2!F:F,Stock2!J:J,"")} | H28: ให้ตั้งแต่ชิ้นแรก All Channel (1-31 Aug 2025)
A29: PANZERGLASS | B29: S31789 | C29: PANZERGLASS Bundle Set for iPhone 16 Pro Max | D29: 2490 | E29: 70 | F29: =IFERROR(VLOOKUP(B29,Stock1!F:J,5,False),"") | G29: {=_xlfn.XLOOKUP(B29,Stock2!F:F,Stock2!J:J,"")} | H29: ให้ตั้งแต่ชิ้นแรก All Channel (1-31 Aug 2025)
F30: =IFERROR(VLOOKUP(B30,Stock1!F:J,5,False),"") | G30: {=_xlfn.XLOOKUP(B30,Stock2!F:F,Stock2!J:J,"")}
A31: BODYGUARDZ | B31: 846237082385 | C31: BODYGUARDZ APEX for iPhone 16 Pro - Black Border | D31: 2790 | E31: 70 | F31: =IFERROR(VLOOKUP(B31,Stock1!F:J,5,False),"") | G31: {=_xlfn.XLOOKUP(B31,Stock2!F:F,Stock2!J:J,"")} | H31: ให้ตั้งแต่ชิ้นแรก All Channel (1-31 Aug 2025)
A32: BODYGUARDZ | B32: 846237082408 | C32: BODYGUARDZ APEX for iPhone 16 Pro Max - Black Border | D32: 2790 | E32: 70 | F32: =IFERROR(VLOOKUP(B32,Stock1!F:J,5,False),"") | G32: {=_xlfn.XLOOKUP(B32,Stock2!F:F,Stock2!J:J,"")} | H32: ให้ตั้งแต่ชิ้นแรก All Channel (1-31 Aug 2025)
F33: =IFERROR(VLOOKUP(B33,Stock1!F:J,5,False),"") | G33: {=_xlfn.XLOOKUP(B33,Stock2!F:F,Stock2!J:J,"")}
A34: PANZERGLASS | B34: 5715685002335 | C34: PANZERGLASS Ultra Wide Fit Matte Gaming for iPhone 16 | D34: 1590 | E34: 20 | F34: =IFERROR(VLOOKUP(B34,Stock1!F:J,5,False),"") | G34: {=_xlfn.XLOOKUP(B34,Stock2!F:F,Stock2!J:J,"")} | H34: ให้ตั้งแต่ชิ้นแรก All channel | 1-31 Aug 2025 (ไม่คู่เครื่อง)
A35: PANZERGLASS | B35: 5715685002373 | C35: PANZERGLASS Ultra Wide Fit for iPhone 16 | D35: 1490 | E35: 20 | F35: =IFERROR(VLOOKUP(B35,Stock1!F:J,5,False),"") | G35: {=_xlfn.XLOOKUP(B35,Stock2!F:F,Stock2!J:J,"")} | H35: ให้ตั้งแต่ชิ้นแรก All channel | 1-30 June 2025 (ไม่คู่เครื่อง)
A36: PANZERGLASS | B36: 5715685002458 | C36: PANZERGLASS Ultra Wide Fit Privacy for iPhone 16 | D36: 1590 | E36: 20 | F36: =IFERROR(VLOOKUP(B36,Stock1!F:J,5,False),"") | G36: {=_xlfn.XLOOKUP(B36,Stock2!F:F,Stock2!J:J,"")} | H36: ให้ตั้งแต่ชิ้นแรก All channel | 1-31 Aug 2025 (ไม่คู่เครื่อง)
A37: PANZERGLASS | B37: 5715685002359 | C37: PANZERGLASS Ultra Wide Fit Matte Gaming for iPhone 16 Plus | D37: 1590 | E37: 20 | F37: =IFERROR(VLOOKUP(B37,Stock1!F:J,5,False),"") | G37: {=_xlfn.XLOOKUP(B37,Stock2!F:F,Stock2!J:J,"")} | H37: ให้ตั้งแต่ชิ้นแรก All channel | 1-31 Aug 2025 (ไม่คู่เครื่อง)
A38: PANZERGLASS | B38: 5715685002397 | C38: PANZERGLASS Ultra Wide Fit for iPhone 16 Plus | D38: 1490 | E38: 20 | F38: =IFERROR(VLOOKUP(B38,Stock1!F:J,5,False),"") | G38: {=_xlfn.XLOOKUP(B38,Stock2!F:F,Stock2!J:J,"")} | H38: ให้ตั้งแต่ชิ้นแรก All channel | 1-31 Aug 2025 (ไม่คู่เครื่อง)
A39: PANZERGLASS | B39: 5715685002472 | C39: PANZERGLASS Ultra Wide Fit Privacy for iPhone 16 Plus | D39: 1590 | E39: 20 | F39: =IFERROR(VLOOKUP(B39,Stock1!F:J,5,False),"") | G39: {=_xlfn.XLOOKUP(B39,Stock2!F:F,Stock2!J:J,"")} | H39: ให้ตั้งแต่ชิ้นแรก All channel | 1-31 Aug 2025 (ไม่คู่เครื่อง)
A40: PANZERGLASS | B40: 5715685002304 | C40: PANZERGLASS Ultra Wide Fit Ceramic for iPhone 16 Pro | D40: 2590 | E40: 20 | F40: =IFERROR(VLOOKUP(B40,Stock1!F:J,5,False),"") | G40: {=_xlfn.XLOOKUP(B40,Stock2!F:F,Stock2!J:J,"")} | H40: ให้ตั้งแต่ชิ้นแรก All channel | 1-31 Aug 2025 (ไม่คู่เครื่อง)
A41: PANZERGLASS | B41: 5715685002342 | C41: PANZERGLASS Ultra Wide Fit Matte Gaming for iPhone 16 Pro | D41: 1590 | E41: 20 | F41: =IFERROR(VLOOKUP(B41,Stock1!F:J,5,False),"") | G41: {=_xlfn.XLOOKUP(B41,Stock2!F:F,Stock2!J:J,"")} | H41: ให้ตั้งแต่ชิ้นแรก All channel | 1-31 Aug 2025 (ไม่คู่เครื่อง)
A42: PANZERGLASS | B42: 5715685002380 | C42: PANZERGLASS Ultra Wide Fit for iPhone 16 Pro | D42: 1490 | E42: 20 | F42: =IFERROR(VLOOKUP(B42,Stock1!F:J,5,False),"") | G42: {=_xlfn.XLOOKUP(B42,Stock2!F:F,Stock2!J:J,"")} | H42: ให้ตั้งแต่ชิ้นแรก All channel | 1-31 Aug 2025 (ไม่คู่เครื่อง)
...

Sheet DATAPremium
A4: P/N | B4: Description | C4: Premium
A5: 2064925400008 | B5: [PM] Umbrella UV Mini Youmi Black | C5: Smartphone 10,000 up
A6: 4897121000134 | B6: [PM] Stand Tablet 360 Rotation | C6: Tablet
A7: 8859289659292 | B7: [PM] Multifunction Metal Holder desktop PH-02 Dpower | C7: Smartphone
A8: 8859289665477 | B8: Premium SAMSUNG TC-04 (Type-C) | C8: Smartphone
A9: 8859289682399 | B9: Premium D-Power Phone Holder PH-03 | C9: Smartphone
A10: 8859289650411 | B10: Premium Bluetooth Speaker PARCO | C10: Smartphone
A11: 8859289657762 | B11: Premium D-Power M22 Speaker Bluetooth | C11: Smartphone 10,000 up
A12: 8859289682863 | B12: [PM] Bluetooth speaker Z2 Dpower | C12: Tablet
A13: PREMIUM0017044 | B13: [PM] Blackpack Fashion Phoenix | C13: Tablet
A14: PREMIUM0017045 | B14: [PM] Blackpack Colorful Phoenix | C14: Tablet
A15: PREMIUM-2025112 | B15: [PM] Wireless Speaker EP Poppy | C15: Tablet
... A81: PM6936678491526 | B81: Premium Robot Portable handheld fan RT-HF01 - White | C81: Smartphone 5,000 up

Sheet Adapter&สาย&Flim
A1: Marketing Name | B1: Model Code | C1: RRP In.vat | D1: Stock ชั้น1 | E1: Stock ชั้น2 | H1: Marketing Name | I1: Model Code | J1: RRP In.vat | K1: Incentive | L1: Stock ชั้น1 | M1: Stock ชั้น2 | P1: Marketing Name | Q1: Model Code | R1: RRP In.vat | S1: Stock ชั้น1 | T1: Stock ชั้น2 | V1: {=_xlfn.XLOOKUP("Charger",Stock1!B1,Stock1!I1,"")} | W1: {=_xlfn.XLOOKUP(V1,Stock1!I1,Stock1!F1,"")} | X1: {=_xlfn.XLOOKUP(V1,Stock1!I1,Stock1!J1,"")} | Y1: {=_xlfn.XLOOKUP("Screen Protector for Android Phone and Other",Stock1!B1,Stock1!I1,"")} | Z1: {=_xlfn.XLOOKUP("Screen Protector for Galaxy Phone",Stock1!B1,Stock1!I1,"")} | AA1: {=_xlfn.XLOOKUP("Screen Protector for Galaxy Tab",Stock1!B1,Stock1!I1,"")} | AB1: =TEXTJOIN(,,Y1,Z1,AA1) | AC1: {=_xlfn.XLOOKUP(AB1,Stock1!I1,Stock1!F1,"")} | AD1: {=_xlfn.XLOOKUP(AB1,Stock1!I1,Stock1!J1,"")} | AE1: {=_xlfn.XLOOKUP("Storage",Stock1!B1,Stock1!I1,"")} | AF1: {=_xlfn.XLOOKUP(AE1,Stock1!I1,Stock1!F1,"")} | AG1: {=_xlfn.XLOOKUP(AE1,Stock1!I1,Stock1!J1,"")}
A2: =UNIQUE(V:V) | B2: =UNIQUE(W:W) | D2: =IFERROR(VLOOKUP(B2,Stock1!F:J,5,False),"") | E2: =IFERROR(VLOOKUP(B2,Stock2!F:J,5,False),"") | H2: =UNIQUE(AB:AB) | I2: =UNIQUE(AC:AC) | L2: =IFERROR(VLOOKUP(I2,Stock1!F:J,5,False),"") | M2: =IFERROR(VLOOKUP(I2,Stock2!F:J,5,False),"") | P2: =UNIQUE(AE:AE) | Q2: =UNIQUE(AF:AF) | S2: =IFERROR(VLOOKUP(Q2,Stock1!F:J,5,False),"") | T2: =IFERROR(VLOOKUP(Q2,Stock2!F:J,5,False),"") | V2: {=_xlfn.XLOOKUP("Charger",Stock1!B2,Stock1!I2,"")} | W2: {=_xlfn.XLOOKUP(V2,Stock1!I2,Stock1!F2,"")} | X2: {=_xlfn.XLOOKUP(V2,Stock1!I2,Stock1!J2,"")} | Y2: {=_xlfn.XLOOKUP("Screen Protector for Android Phone and Other",Stock1!B2,Stock1!I2,"")} | Z2: {=_xlfn.XLOOKUP("Screen Protector for Galaxy Phone",Stock1!B2,Stock1!I2,"")} | AA2: {=_xlfn.XLOOKUP("Screen Protector for Galaxy Tab",Stock1!B2,Stock1!I2,"")} | AB2: =TEXTJOIN(,,Y2,Z2,AA2) | AC2: {=_xlfn.XLOOKUP(AB2,Stock1!I2,Stock1!F2,"")} | AD2: {=_xlfn.XLOOKUP(AB2,Stock1!I2,Stock1!J2,"")} | AE2: {=_xlfn.XLOOKUP("Storage",Stock1!B2,Stock1!I2,"")} | AF2: {=_xlfn.XLOOKUP(AE2,Stock1!I2,Stock1!F2,"")} | AG2: {=_xlfn.XLOOKUP(AE2,Stock1!I2,Stock1!J2,"")}
A3: [CS]UGREEN UNO RG 65W USB A*1 + USB C*2 GaN Fast Charger THAI PLUG - Gray | B3: 6941876238958 | C3: {=IFERROR(_xlfn.XLOOKUP(B3,Stock1!F:F,Stock1!E:E,""),"")} -> 999 | D3: =IFERROR(VLOOKUP(B3,Stock1!F:J,5,False),"") -> 8 | E3: =IFERROR(VLOOKUP(B3,Stock2!F:J,5,False),"") -> 2 | H3: [CS]Focus TG FF Samsung Galaxy A07 Black | I3: 8859703436409 | J3: {=IFERROR(_xlfn.XLOOKUP(I3,Stock1!F:F,Stock1!E:E,""),"")} -> 249 | K3: {=IFERROR(_xlfn.XLOOKUP(I3,Incentive!B:B,Incentive!E:E,""),"")} | L3: =IFERROR(VLOOKUP(I3,Stock1!F:J,5,False),"") -> 10 | M3: =IFERROR(VLOOKUP(I3,Stock2!F:J,5,False),"") -> 10 | P3: #REF! | Q3: #REF! | R3: {=IFERROR(_xlfn.XLOOKUP(Q3,Stock1!F:F,Stock1!E:E,""),"")} | S3: =IFERROR(VLOOKUP(Q3,Stock1!F:J,5,False),"") | T3: =IFERROR(VLOOKUP(Q3,Stock2!F:J,5,False),"") | V3: {=_xlfn.XLOOKUP("Charger",Stock1!B3,Stock1!I3,"")} | W3: {=_xlfn.XLOOKUP(V3,Stock1!I3,Stock1!F3,"")} | X3: {=_xlfn.XLOOKUP(V3,Stock1!I3,Stock1!J3,"")} | Y3: {=_xlfn.XLOOKUP("Screen Protector for Android Phone and Other",Stock1!B3,Stock1!I3,"")} | Z3: {=_xlfn.XLOOKUP("Screen Protector for Galaxy Phone",Stock1!B3,Stock1!I3,"")} | AA3: {=_xlfn.XLOOKUP("Screen Protector for Galaxy Tab",Stock1!B3,Stock1!I3,"")} | AB3: =TEXTJOIN(,,Y3,Z3,AA3) | AC3: {=_xlfn.XLOOKUP(AB3,Stock1!I3,Stock1!F3,"")} | AD3: {=_xlfn.XLOOKUP(AB3,Stock1!I3,Stock1!J3,"")} | AE3: {=_xlfn.XLOOKUP("Storage",Stock1!B3,Stock1!I3,"")} | AF3: {=_xlfn.XLOOKUP(AE3,Stock1!I3,Stock1!F3,"")} | AG3: {=_xlfn.XLOOKUP(AE3,Stock1!I3,Stock1!J3,"")}
A4: [CS]UGREEN Wall Charer 30W USB Port*1 + PD*2 Fast Charger Thai plug - Grey | B4: 6941876265732 | C4: {=IFERROR(_xlfn.XLOOKUP(B4,Stock1!F:F,Stock1!E:E,""),"")} -> 399 | D4: =IFERROR(VLOOKUP(B4,Stock1!F:J,5,False),"") -> 48 | E4: =IFERROR(VLOOKUP(B4,Stock2!F:J,5,False),"") -> 9 | H4: [CS]HISHIELD TemperedGlass FC 2.5D Samsung A07 | I4: 8859216804023 | J4: {=IFERROR(_xlfn.XLOOKUP(I4,Stock1!F:F,Stock1!E:E,""),"")} -> 299 | K4: {=IFERROR(_xlfn.XLOOKUP(I4,Incentive!B:B,Incentive!E:E,""),"")} | L4: =IFERROR(VLOOKUP(I4,Stock1!F:J,5,False),"") -> 7 | M4: =IFERROR(VLOOKUP(I4,Stock2!F:J,5,False),"") -> 15 | R4: {=IFERROR(_xlfn.XLOOKUP(Q4,Stock1!F:F,Stock1!E:E,""),"")} | S4: =IFERROR(VLOOKUP(Q4,Stock1!F:J,5,False),"") | T4: =IFERROR(VLOOKUP(Q4,Stock2!F:J,5,False),"") | V4: {=_xlfn.XLOOKUP("Charger",Stock1!B4,Stock1!I4,"")} | W4: {=_xlfn.XLOOKUP(V4,Stock1!I4,Stock1!F4,"")} | X4: {=_xlfn.XLOOKUP(V4,Stock1!I4,Stock1!J4,"")} | Y4: {=_xlfn.XLOOKUP("Screen Protector for Android Phone and Other",Stock1!B4,Stock1!I4,"")} | Z4: {=_xlfn.XLOOKUP("Screen Protector for Galaxy Phone",Stock1!B4,Stock1!I4,"")} | AA4: {=_xlfn.XLOOKUP("Screen Protector for Galaxy Tab",Stock1!B4,Stock1!I4,"")} | AB4: =TEXTJOIN(,,Y4,Z4,AA4) | AC4: {=_xlfn.XLOOKUP(AB4,Stock1!I4,Stock1!F4,"")} | AD4: {=_xlfn.XLOOKUP(AB4,Stock1!I4,Stock1!J4,"")} | AE4: {=_xlfn.XLOOKUP("Storage",Stock1!B4,Stock1!I4,"")} | AF4: {=_xlfn.XLOOKUP(AE4,Stock1!I4,Stock1!F4,"")} | AG4: {=_xlfn.XLOOKUP(AE4,Stock1!I4,Stock1!J4,"")}
A5: [CS]UGREEN Wall Charger 45W USB Port*1 + PD*2 Fast Charger Thai plug - Grey | B5: 6941876265749 | C5: {=IFERROR(_xlfn.XLOOKUP(B5,Stock1!F:F,Stock1!E:E,""),"")} -> 599 | D5: =IFERROR(VLOOKUP(B5,Stock1!F:J,5,False),"") -> 9 | E5: =IFERROR(VLOOKUP(B5,Stock2!F:J,5,False),"") -> 10 | H5: [CS]HISHIELD TemperedGlass FC 2.5D Samsung A17 | I5: 8859216803910 | J5: {=IFERROR(_xlfn.XLOOKUP(I5,Stock1!F:F,Stock1!E:E,""),"")} -> 299 | K5: {=IFERROR(_xlfn.XLOOKUP(I5,Incentive!B:B,Incentive!E:E,""),"")} | L5: =IFERROR(VLOOKUP(I5,Stock1!F:J,5,False),"") -> 17 | M5: =IFERROR(VLOOKUP(I5,Stock2!F:J,5,False),"") -> 33 | R5: {=IFERROR(_xlfn.XLOOKUP(Q5,Stock1!F:F,Stock1!E:E,""),"")} | S5: =IFERROR(VLOOKUP(Q5,Stock1!F:J,5,False),"") | T5: =IFERROR(VLOOKUP(Q5,Stock2!F:J,5,False),"") | V5: {=_xlfn.XLOOKUP("Charger",Stock1!B5,Stock1!I5,"")} | W5: {=_xlfn.XLOOKUP(V5,Stock1!I5,Stock1!F5,"")} | X5: {=_xlfn.XLOOKUP(V5,Stock1!I5,Stock1!J5,"")} | Y5: {=_xlfn.XLOOKUP("Screen Protector for Android Phone and Other",Stock1!B5,Stock1!I5,"")} | Z5: {=_xlfn.XLOOKUP("Screen Protector for Galaxy Phone",Stock1!B5,Stock1!I5,"")} | AA5: {=_xlfn.XLOOKUP("Screen Protector for Galaxy Tab",Stock1!B5,Stock1!I5,"")} | AB5: =TEXTJOIN(,,Y5,Z5,AA5) | AC5: {=_xlfn.XLOOKUP(AB5,Stock1!I5,Stock1!F5,"")} | AD5: {=_xlfn.XLOOKUP(AB5,Stock1!I5,Stock1!J5,"")} | AE5: {=_xlfn.XLOOKUP("Storage",Stock1!B5,Stock1!I5,"")} | AF5: {=_xlfn.XLOOKUP(AE5,Stock1!I5,Stock1!F5,"")} | AG5: {=_xlfn.XLOOKUP(AE5,Stock1!I5,Stock1!J5,"")}
A6: Samsung Adapter 25W No Cable-Black | B6: EP-T2510NBEGTH | C6: {=IFERROR(_xlfn.XLOOKUP(B6,Stock1!F:F,Stock1!E:E,""),"")} -> 690 | D6: =IFERROR(VLOOKUP(B6,Stock1!F:J,5,False),"") -> 52 | E6: =IFERROR(VLOOKUP(B6,Stock2!F:J,5,False),"") -> 36 | H6: [CS]Focus TG FF Samsung Galaxy A26 5G/A17 5G Black | I6: 8859703433569 | J6: {=IFERROR(_xlfn.XLOOKUP(I6,Stock1!F:F,Stock1!E:E,""),"")} -> 249 | K6: {=IFERROR(_xlfn.XLOOKUP(I6,Incentive!B:B,Incentive!E:E,""),"")} -> 10 | L6: =IFERROR(VLOOKUP(I6,Stock1!F:J,5,False),"") -> 4 | M6: =IFERROR(VLOOKUP(I6,Stock2!F:J,5,False),"") -> 13 | R6: {=IFERROR(_xlfn.XLOOKUP(Q6,Stock1!F:F,Stock1!E:E,""),"")} | S6: =IFERROR(VLOOKUP(Q6,Stock1!F:J,5,False),"") | T6: =IFERROR(VLOOKUP(Q6,Stock2!F:J,5,False),"") | V6: {=_xlfn.XLOOKUP("Charger",Stock1!B6,Stock1!I6,"")} | W6: {=_xlfn.XLOOKUP(V6,Stock1!I6,Stock1!F6,"")} | X6: {=_xlfn.XLOOKUP(V6,Stock1!I6,Stock1!J6,"")} | Y6: {=_xlfn.XLOOKUP("Screen Protector for Android Phone and Other",Stock1!B6,Stock1!I6,"")} | Z6: {=_xlfn.XLOOKUP("Screen Protector for Galaxy Phone",Stock1!B6,Stock1!I6,"")} | AA6: {=_xlfn.XLOOKUP("Screen Protector for Galaxy Tab",Stock1!B6,Stock1!I6,"")} | AB6: =TEXTJOIN(,,Y6,Z6,AA6) | AC6: {=_xlfn.XLOOKUP(AB6,Stock1!I6,Stock1!F6,"")} | AD6: {=_xlfn.XLOOKUP(AB6,Stock1!I6,Stock1!J6,"")} | AE6: {=_xlfn.XLOOKUP("Storage",Stock1!B6,Stock1!I6,"")} | AF6: {=_xlfn.XLOOKUP(AE6,Stock1!I6,Stock1!F6,"")} | AG6: {=_xlfn.XLOOKUP(AE6,Stock1!I6,Stock1!J6,"")}
A7: Samsung Adapter 25W No Cable-White | B7: EP-T2510NWEGTH | C7: {=IFERROR(_xlfn.XLOOKUP(B7,Stock1!F:F,Stock1!E:E,""),"")} -> 690 | D7: =IFERROR(VLOOKUP(B7,Stock1!F:J,5,False),"") -> 42 | E7: =IFERROR(VLOOKUP(B7,Stock2!F:J,5,False),"") -> 31 | H7: [CS]Focus TG FF Samsung Galaxy A27 5G Black | I7: 8859703443339 | J7: {=IFERROR(_xlfn.XLOOKUP(I7,Stock1!F:F,Stock1!E:E,""),"")} -> 249 | K7: {=IFERROR(_xlfn.XLOOKUP(I7,Incentive!B:B,Incentive!E:E,""),"")} | L7: =IFERROR(VLOOKUP(I7,Stock1!F:J,5,False),"") -> 12 | M7: =IFERROR(VLOOKUP(I7,Stock2!F:J,5,False),"") | R7: {=IFERROR(_xlfn.XLOOKUP(Q7,Stock1!F:F,Stock1!E:E,""),"")} | S7: =IFERROR(VLOOKUP(Q7,Stock1!F:J,5,False),"") | T7: =IFERROR(VLOOKUP(Q7,Stock2!F:J,5,False),"") | V7: {=_xlfn.XLOOKUP("Charger",Stock1!B7,Stock1!I7,"")} | W7: {=_xlfn.XLOOKUP(V7,Stock1!I7,Stock1!F7,"")} | X7: {=_xlfn.XLOOKUP(V7,Stock1!I7,Stock1!J7,"")} | Y7: {=_xlfn.XLOOKUP("Screen Protector for Android Phone and Other",Stock1!B7,Stock1!I7,"")} | Z7: {=_xlfn.XLOOKUP("Screen Protector for Galaxy Phone",Stock1!B7,Stock1!I7,"")} | AA7: {=_xlfn.XLOOKUP("Screen Protector for Galaxy Tab",Stock1!B7,Stock1!I7,"")} | AB7: =TEXTJOIN(,,Y7,Z7,AA7) | AC7: {=_xlfn.XLOOKUP(AB7,Stock1!I7,Stock1!F7,"")} | AD7: {=_xlfn.XLOOKUP(AB7,Stock1!I7,Stock1!J7,"")} | AE7: {=_xlfn.XLOOKUP("Storage",Stock1!B7,Stock1!I7,"")} | AF7: {=_xlfn.XLOOKUP(AE7,Stock1!I7,Stock1!F7,"")} | AG7: {=_xlfn.XLOOKUP(AE7,Stock1!I7,Stock1!J7,"")}
A8: Samsung Adapter 45W Fastcharge with Cable - Black | B8: EP-T4511XBEGTH | C8: {=IFERROR(_xlfn.XLOOKUP(B8,Stock1!F:F,Stock1!E:E,""),"")} -> 1290 | D8: =IFERROR(VLOOKUP(B8,Stock1!F:J,5,False),"") -> 7 | E8: =IFERROR(VLOOKUP(B8,Stock2!F:J,5,False),"") -> 1 | H8: [CS]Hishield Tempered Glass FC 2.5D for Samsung A37 | I8: 8859216846719 | J8: {=IFERROR(_xlfn.XLOOKUP(I8,Stock1!F:F,Stock1!E:E,""),"")} -> 299 | K8: {=IFERROR(_xlfn.XLOOKUP(I8,Incentive!B:B,Incentive!E:E,""),"")} | L8: =IFERROR(VLOOKUP(I8,Stock1!F:J,5,False),"") -> 35 | M8: =IFERROR(VLOOKUP(I8,Stock2!F:J,5,False),"") -> 18 | R8: {=IFERROR(_xlfn.XLOOKUP(Q8,Stock1!F:F,Stock1!E:E,""),"")} | S8: =IFERROR(VLOOKUP(Q8,Stock1!F:J,5,False),"") | T8: =IFERROR(VLOOKUP(Q8,Stock2!F:J,5,False),"") | V8: {=_xlfn.XLOOKUP("Charger",Stock1!B8,Stock1!I8,"")} | W8: {=_xlfn.XLOOKUP(V8,Stock1!I8,Stock1!F8,"")} | X8: {=_xlfn.XLOOKUP(V8,Stock1!I8,Stock1!J8,"")} | Y8: {=_xlfn.XLOOKUP("Screen Protector for Android Phone and Other",Stock1!B8,Stock1!I8,"")} | Z8: {=_xlfn.XLOOKUP("Screen Protector for Galaxy Phone",Stock1!B8,Stock1!I8,"")} | AA8: {=_xlfn.XLOOKUP("Screen Protector for Galaxy Tab",Stock1!B8,Stock1!I8,"")} | AB8: =TEXTJOIN(,,Y8,Z8,AA8) | AC8: {=_xlfn.XLOOKUP(AB8,Stock1!I8,Stock1!F8,"")} | AD8: {=_xlfn.XLOOKUP(AB8,Stock1!I8,Stock1!J8,"")} | AE8: {=_xlfn.XLOOKUP("Storage",Stock1!B8,Stock1!I8,"")} | AF8: {=_xlfn.XLOOKUP(AE8,Stock1!I8,Stock1!F8,"")} | AG8: {=_xlfn.XLOOKUP(AE8,Stock1!I8,Stock1!J8,"")}
A9: Samsung Adapter 45W Fastcharge with Cable (SIS) - Black | B9: SSG-EP-T4511XBEGTH | C9: {=IFERROR(_xlfn.XLOOKUP(B9,Stock1!F:F,Stock1!E:E,""),"")} -> 1290 | D9: =IFERROR(VLOOKUP(B9,Stock1!F:J,5,False),"") -> 43 | E9: =IFERROR(VLOOKUP(B9,Stock2!F:J,5,False),"") -> 25 | H9: [CS]Hishield Tempered Glass FC 2.5D for Samsung A57 | I9: 8859216846726 | J9: {=IFERROR(_xlfn.XLOOKUP(I9,Stock1!F:F,Stock1!E:E,""),"")} -> 299 | K9: {=IFERROR(_xlfn.XLOOKUP(I9,Incentive!B:B,Incentive!E:E,""),"")} | L9: =IFERROR(VLOOKUP(I9,Stock1!F:J,5,False),"") -> 10 | M9: =IFERROR(VLOOKUP(I9,Stock2!F:J,5,False),"") -> 29 | R9: {=IFERROR(_xlfn.XLOOKUP(Q9,Stock1!F:F,Stock1!E:E,""),"")} | S9: =IFERROR(VLOOKUP(Q9,Stock1!F:J,5,False),"") | T9: =IFERROR(VLOOKUP(Q9,Stock2!F:J,5,False),"") | V9: {=_xlfn.XLOOKUP("Charger",Stock1!B9,Stock1!I9,"")} | W9: {=_xlfn.XLOOKUP(V9,Stock1!I9,Stock1!F9,"")} | X9: {=_xlfn.XLOOKUP(V9,Stock1!I9,Stock1!J9,"")} | Y9: {=_xlfn.XLOOKUP("Screen Protector for Android Phone and Other",Stock1!B9,Stock1!I9,"")} | Z9: {=_xlfn.XLOOKUP("Screen Protector for Galaxy Phone",Stock1!B9,Stock1!I9,"")} | AA9: {=_xlfn.XLOOKUP("Screen Protector for Galaxy Tab",Stock1!B9,Stock1!I9,"")} | AB9: =TEXTJOIN(,,Y9,Z9,AA9) | AC9: {=_xlfn.XLOOKUP(AB9,Stock1!I9,Stock1!F9,"")} | AD9: {=_xlfn.XLOOKUP(AB9,Stock1!I9,Stock1!J9,"")} | AE9: {=_xlfn.XLOOKUP("Storage",Stock1!B9,Stock1!I9,"")} | AF9: {=_xlfn.XLOOKUP(AE9,Stock1!I9,Stock1!F9,"")} | AG9: {=_xlfn.XLOOKUP(AE9,Stock1!I9,Stock1!J9,"")}
